Workbook

Sheet INDICE
B2: INDICE DE INFORMACION DE LA INDUSTRIA
B3: (Hacer click sobre el titulo de interes)
A5: 1 | B5: ='Inventario Empresas Linea 1'!C2 -> EMPRESAS CON INVENTARIO CLIMATIZACIO
A6: 2 | B6: ='Inventario Empresas Linea 2'!C2 -> EMPRESAS CON INVENTARIO ELECTRODOMES
A7: 3 | B7: ='Manufactura Linea 1'!C4 -> COSTO PROMEDIO DE MANUFACTURA PARA CLIMATIZACIO CONSIDERANDO TODA LA INDUSTRIA
A8: 4 | B8: ='Manufactura Linea 2'!C4 -> COSTO PROMEDIO DE MANUFACTURA PARA ELECTRODOMES CONSIDERANDO TODA LA INDUSTRIA
A9: 5 | B9: =CONCATENATE('Informacion Linea 1'!C1," ",'Informacion Linea 1'!D1) -> INFORMACION DETALLADA PARA CLIMATIZACIO
A10: 6 | B10: =CONCATENATE('Informacion Linea 1'!C58," ",'Informacion Linea 1'!D1) -> GASTOS HISTORICOS PROMEDIO CONSIDERANDO CLIMATIZACIO
A11: 7 | B11: =CONCATENATE('Informacion Linea 2'!C1," ",'Informacion Linea 2'!D1) -> INFORMACION DETALLADA PARA ELECTRODOMES
A12: 8 | B12: =CONCATENATE('Informacion Linea 2'!C58," ",'Informacion Linea 2'!D1) -> GASTOS HISTORICOS PROMEDIO CONSIDERANDO ELECTRODOMES
A13: 9 | B13: ='Rentabilidad Linea 1'!C3 -> RENTABILIDAD POR ARTICULO DE CLIMATIZACIO
A14: 10 | B14: ='Rentabilidad Linea 2'!C3 -> RENTABILIDAD POR ARTICULO DE ELECTRODOMES
A15: 11 | B15: ='Precios Promedios'!C3 -> PRECIOS DE EXPEDITAJE (NO SE RECOMIENDA USAR ESTOS COMO REFERENCIA PARA DETERMINAR PRECIOS
A16: 12 | B16: ='Precios Promedios'!C15 -> PRECIOS DE COMPRAS DE SALDOS
A17: 13 | B17: ='Vta Industria Linea 1'!C3 -> PRECIO PROMEDIO TRANSADO ENTRE EMPRESAS POR ARTICULO Y CANTIDAD PARA EL PERIODO 7 SEGUN EL TRANSPORTE. PARA CLIMATIZACIO
A18: 14 | B18: ='Vta Industria Linea 2'!C3 -> PRECIO PROMEDIO TRANSADO ENTRE EMPRESAS POR ARTICULO Y CANTIDAD PARA EL PERIODO 7 SEGUN EL TRANSPORTE. PARA ELECTRODOMES
A19: 15 | B19: ='Actividad Empresas'!C3 -> EMPRESAS CON ACTIVIDAD
A20: 16 | B20: ='Fabricas sin Uso'!C2 -> FABRICAS QUE NO HAN SIDO UTILIZADAS EL ULTIMO PERIODO

Sheet Inventario Empresas Linea 1
C2: =UPPER(DATALOG!B651) -> EMPRESAS CON INVENTARIO CLIMATIZACIO
C3: =IF(DATALOG!C651="","",DATALOG!C651) -> Alemania | D3: =IF(DATALOG!D651="","",DATALOG!D651) -> Alemania | E3: =IF(DATALOG!E651="","",DATALOG!E651) -> Australia | F3: =IF(DATALOG!F651="","",DATALOG!F651) -> Australia | G3: =IF(DATALOG!G651="","",DATALOG!G651) -> Espana | H3: =IF(DATALOG!H651="","",DATALOG!H651) -> Espana | I3: =IF(DATALOG!I651="","",DATALOG!I651) | J3: =IF(DATALOG!J651="","",DATALOG!J651) -> Alemania | ... BL3: =IF(DATALOG!BL651="","",DATALOG!BL651)
C4: =IF(DATALOG!C652="","",DATALOG!C652) -> EstufaGas | D4: =IF(DATALOG!D652="","",DATALOG!D652) -> Inventario | E4: =IF(DATALOG!E652="","",DATALOG!E652) -> EstufaGas | F4: =IF(DATALOG!F652="","",DATALOG!F652) -> Inventario | G4: =IF(DATALOG!G652="","",DATALOG!G652) -> EstufaGas | H4: =IF(DATALOG!H652="","",DATALOG!H652) -> Inventario | I4: =IF(DATALOG!I652="","",DATALOG!I652) | J4: =IF(DATALOG!J652="","",DATALOG!J652) -> EstufaElectr | ... BL4: =IF(DATALOG!BL652="","",DATALOG!BL652)
C5: =IF(DATALOG!C653=0,"",DATALOG!C653) -> 2 | D5: =IF(DATALOG!D653=0,"",DATALOG!D653) -> 7744 | E5: =IF(DATALOG!E653=0,"",DATALOG!E653) -> 4 | F5: =IF(DATALOG!F653=0,"",DATALOG!F653) -> 6619 | G5: =IF(DATALOG!G653=0,"",DATALOG!G653) -> 2 | H5: =IF(DATALOG!H653=0,"",DATALOG!H653) -> 9800 | I5: =IF(DATALOG!I653=0,"",DATALOG!I653) | J5: =IF(DATALOG!J653=0,"",DATALOG!J653) -> 2 | ... O5: =IF(DATALOG!O653=0,"",DATALOG!O653) -> 2000 | Q5: =IF(DATALOG!Q653=0,"",DATALOG!Q653) -> 7 | R5: =IF(DATALOG!R653=0,"",DATALOG!R653) -> 7201 | S5: =IF(DATALOG!S653=0,"",DATALOG!S653) -> 4 | T5: =IF(DATALOG!T653=0,"",DATALOG!T653) -> 4749 | U5: =IF(DATALOG!U653=0,"",DATALOG!U653) -> 4 | V5: =IF(DATALOG!V653=0,"",DATALOG!V653) -> 5052 | X5: =IF(DATALOG!X653=0,"",DATALOG!X653) -> 5 | Y5: =IF(DATALOG!Y653=0,"",DATALOG!Y653) -> 36000 | Z5: =IF(DATALOG!Z653=0,"",DATALOG!Z653) -> 4 | AA5: =IF(DATALOG!AA653=0,"",DATALOG!AA653) -> 5719 | AB5: =IF(DATALOG!AB653=0,"",DATALOG!AB653) -> 4 | AC5: =IF(DATALOG!AC653=0,"",DATALOG!AC653) -> 2517 | AE5: =IF(DATALOG!AE653=0,"",DATALOG!AE653) -> 2 | AF5: =IF(DATALOG!AF653=0,"",DATALOG!AF653) -> 6303 | AG5: =IF(DATALOG!AG653=0,"",DATALOG!AG653) -> 2 | AH5: =IF(DATALOG!AH653=0,"",DATALOG!AH653) -> 10000 | AI5: =IF(DATALOG!AI653=0,"",DATALOG!AI653) -> 2 | AJ5: =IF(DATALOG!AJ653=0,"",DATALOG!AJ653) -> 7000 | AL5: =IF(DATALOG!AL653=0,"",DATALOG!AL653) -> 2 | AM5: =IF(DATALOG!AM653=0,"",DATALOG!AM653) -> 5477 | AN5: =IF(DATALOG!AN653=0,"",DATALOG!AN653) -> 2 | AO5: =IF(DATALOG!AO653=0,"",DATALOG!AO653) -> 8333 | AP5: =IF(DATALOG!AP653=0,"",DATALOG!AP653) -> 2 | AQ5: =IF(DATALOG!AQ653=0,"",DATALOG!AQ653) -> 2000 | AS5: =IF(DATALOG!AS653=0,"",DATALOG!AS653) -> 10 | AT5: =IF(DATALOG!AT653=0,"",DATALOG!AT653) -> 1601 | AU5: =IF(DATALOG!AU653=0,"",DATALOG!AU653) -> 2 | AV5: =IF(DATALOG!AV653=0,"",DATALOG!AV653) -> 12500 | AW5: =IF(DATALOG!AW653=0,"",DATALOG!AW653) -> 2 | AX5: =IF(DATALOG!AX653=0,"",DATALOG!AX653) -> 2000 | AZ5: =IF(DATALOG!AZ653=0,"",DATALOG!AZ653) | BA5: =IF(DATALOG!BA653=0,"",DATALOG!BA653) | BB5: =IF(DATALOG!BB653=0,"",DATALOG!BB653) | BC5: =IF(DATALOG!BC653=0,"",DATALOG!BC653) | BD5: =IF(DATALOG!BD653=0,"",DATALOG!BD653) | BE5: =IF(DATALOG!BE653=0,"",DATALOG!BE653) | BG5: =IF(DATALOG!BG653=0,"",DATALOG!BG653) | BH5: =IF(DATALOG!BH653=0,"",DATALOG!BH653) | BI5: =IF(DATALOG!BI653=0,"",DATALOG!BI653) | BJ5: =IF(DATALOG!BJ653=0,"",DATALOG!BJ653) | BK5: =IF(DATALOG!BK653=0,"",DATALOG!BK653) | BL5: =IF(DATALOG!BL653=0,"",DATALOG!BL653)
C6: =IF(DATALOG!C654=0,"",DATALOG!C654) -> 8 | D6: =IF(DATALOG!D654=0,"",DATALOG!D654) -> 12387 | E6: =IF(DATALOG!E654=0,"",DATALOG!E654) -> 11 | F6: =IF(DATALOG!F654=0,"",DATALOG!F654) -> 3356 | G6: =IF(DATALOG!G654=0,"",DATALOG!G654) -> 4 | H6: =IF(DATALOG!H654=0,"",DATALOG!H654) -> 1127 | I6: =IF(DATALOG!I654=0,"",DATALOG!I654) | J6: =IF(DATALOG!J654=0,"",DATALOG!J654) -> 5 | ... O6: =IF(DATALOG!O654=0,"",DATALOG!O654) -> 4252 | Q6: =IF(DATALOG!Q654=0,"",DATALOG!Q654) -> 12 | R6: =IF(DATALOG!R654=0,"",DATALOG!R654) -> 10386 | S6: =IF(DATALOG!S654=0,"",DATALOG!S654) -> 5 | T6: =IF(DATALOG!T654=0,"",DATALOG!T654) -> 2784 | U6: =IF(DATALOG!U654=0,"",DATALOG!U654) -> 6 | V6: =IF(DATALOG!V654=0,"",DATALOG!V654) -> 4002 | X6: =IF(DATALOG!X654=0,"",DATALOG!X654) -> 12 | Y6: =IF(DATALOG!Y654=0,"",DATALOG!Y654) -> 3299 | Z6: =IF(DATALOG!Z654=0,"",DATALOG!Z654) -> 5 | AA6: =IF(DATALOG!AA654=0,"",DATALOG!AA654) -> 7700 | AB6: =IF(DATALOG!AB654=0,"",DATALOG!AB654) -> 6 | AC6: =IF(DATALOG!AC654=0,"",DATALOG!AC654) -> 4000 | AE6: =IF(DATALOG!AE654=0,"",DATALOG!AE654) -> 7 | AF6: =IF(DATALOG!AF654=0,"",DATALOG!AF654) -> 8760 | AG6: =IF(DATALOG!AG654=0,"",DATALOG!AG654) -> 4 | AH6: =IF(DATALOG!AH654=0,"",DATALOG!AH654) -> 6327 | AI6: =IF(DATALOG!AI654=0,"",DATALOG!AI654) -> 4 | AJ6: =IF(DATALOG!AJ654=0,"",DATALOG!AJ654) -> 4552 | AL6: =IF(DATALOG!AL654=0,"",DATALOG!AL654) -> 9 | AM6: =IF(DATALOG!AM654=0,"",DATALOG!AM654) -> 6140 | AN6: =IF(DATALOG!AN654=0,"",DATALOG!AN654) -> 4 | AO6: =IF(DATALOG!AO654=0,"",DATALOG!AO654) -> 2000 | AP6: =IF(DATALOG!AP654=0,"",DATALOG!AP654) -> 8 | AQ6: =IF(DATALOG!AQ654=0,"",DATALOG!AQ654) -> 5820 | AS6: =IF(DATALOG!AS654=0,"",DATALOG!AS654) -> 12 | AT6: =IF(DATALOG!AT654=0,"",DATALOG!AT654) -> 2666 | AU6: =IF(DATALOG!AU654=0,"",DATALOG!AU654) -> 4 | AV6: =IF(DATALOG!AV654=0,"",DATALOG!AV654) -> 4000 | AW6: =IF(DATALOG!AW654=0,"",DATALOG!AW654) -> 8 | AX6: =IF(DATALOG!AX654=0,"",DATALOG!AX654) -> 8500 | AZ6: =IF(DATALOG!AZ654=0,"",DATALOG!AZ654) | BA6: =IF(DATALOG!BA654=0,"",DATALOG!BA654) | BB6: =IF(DATALOG!BB654=0,"",DATALOG!BB654) | BC6: =IF(DATALOG!BC654=0,"",DATALOG!BC654) | BD6: =IF(DATALOG!BD654=0,"",DATALOG!BD654) | BE6: =IF(DATALOG!BE654=0,"",DATALOG!BE654) | BG6: =IF(DATALOG!BG654=0,"",DATALOG!BG654) | BH6: =IF(DATALOG!BH654=0,"",DATALOG!BH654) | BI6: =IF(DATALOG!BI654=0,"",DATALOG!BI654) | BJ6: =IF(DATALOG!BJ654=0,"",DATALOG!BJ654) | BK6: =IF(DATALOG!BK654=0,"",DATALOG!BK654) | BL6: =IF(DATALOG!BL654=0,"",DATALOG!BL654)
C7: =IF(DATALOG!C655=0,"",DATALOG!C655) -> 10 | D7: =IF(DATALOG!D655=0,"",DATALOG!D655) -> 5000 | E7: =IF(DATALOG!E655=0,"",DATALOG!E655) -> 12 | F7: =IF(DATALOG!F655=0,"",DATALOG!F655) -> 4000 | G7: =IF(DATALOG!G655=0,"",DATALOG!G655) -> 6 | H7: =IF(DATALOG!H655=0,"",DATALOG!H655) -> 7637 | I7: =IF(DATALOG!I655=0,"",DATALOG!I655) | J7: =IF(DATALOG!J655=0,"",DATALOG!J655) -> 7 | ... O7: =IF(DATALOG!O655=0,"",DATALOG!O655) -> 6110 | Q7: =IF(DATALOG!Q655=0,"",DATALOG!Q655) -> 13 | R7: =IF(DATALOG!R655=0,"",DATALOG!R655) -> 2990 | S7: =IF(DATALOG!S655=0,"",DATALOG!S655) -> 10 | T7: =IF(DATALOG!T655=0,"",DATALOG!T655) -> 2700 | U7: =IF(DATALOG!U655=0,"",DATALOG!U655) -> 11 | V7: =IF(DATALOG!V655=0,"",DATALOG!V655) -> 6000 | X7: =IF(DATALOG!X655=0,"",DATALOG!X655) -> 13 | Y7: =IF(DATALOG!Y655=0,"",DATALOG!Y655) -> 3000 | Z7: =IF(DATALOG!Z655=0,"",DATALOG!Z655) -> 6 | AA7: =IF(DATALOG!AA655=0,"",DATALOG!AA655) -> 12897 | AB7: =IF(DATALOG!AB655=0,"",DATALOG!AB655) -> 10 | AC7: =IF(DATALOG!AC655=0,"",DATALOG!AC655) -> 6000 | AE7: =IF(DATALOG!AE655=0,"",DATALOG!AE655) -> 8 | AF7: =IF(DATALOG!AF655=0,"",DATALOG!AF655) -> 30000 | AG7: =IF(DATALOG!AG655=0,"",DATALOG!AG655) -> 5 | AH7: =IF(DATALOG!AH655=0,"",DATALOG!AH655) -> 6000 | AI7: =IF(DATALOG!AI655=0,"",DATALOG!AI655) -> 6 | AJ7: =IF(DATALOG!AJ655=0,"",DATALOG!AJ655) -> 8450 | AL7: =IF(DATALOG!AL655=0,"",DATALOG!AL655) -> 12 | AM7: =IF(DATALOG!AM655=0,"",DATALOG!AM655) -> 2703 | AN7: =IF(DATALOG!AN655=0,"",DATALOG!AN655) -> 6 | AO7: =IF(DATALOG!AO655=0,"",DATALOG!AO655) -> 8831 | AP7: =IF(DATALOG!AP655=0,"",DATALOG!AP655) -> 11 | AQ7: =IF(DATALOG!AQ655=0,"",DATALOG!AQ655) -> 4083 | AS7: =IF(DATALOG!AS655=0,"",DATALOG!AS655) -> 13 | AT7: =IF(DATALOG!AT655=0,"",DATALOG!AT655) -> 6720 | AU7: =IF(DATALOG!AU655=0,"",DATALOG!AU655) -> 6 | AV7: =IF(DATALOG!AV655=0,"",DATALOG!AV655) -> 11266 | AW7: =IF(DATALOG!AW655=0,"",DATALOG!AW655) -> 10 | AX7: =IF(DATALOG!AX655=0,"",DATALOG!AX655) -> 3000 | AZ7: =IF(DATALOG!AZ655=0,"",DATALOG!AZ655) | BA7: =IF(DATALOG!BA655=0,"",DATALOG!BA655) | BB7: =IF(DATALOG!BB655=0,"",DATALOG!BB655) | BC7: =IF(DATALOG!BC655=0,"",DATALOG!BC655) | BD7: =IF(DATALOG!BD655=0,"",DATALOG!BD655) | BE7: =IF(DATALOG!BE655=0,"",DATALOG!BE655) | BG7: =IF(DATALOG!BG655=0,"",DATALOG!BG655) | BH7: =IF(DATALOG!BH655=0,"",DATALOG!BH655) | BI7: =IF(DATALOG!BI655=0,"",DATALOG!BI655) | BJ7: =IF(DATALOG!BJ655=0,"",DATALOG!BJ655) | BK7: =IF(DATALOG!BK655=0,"",DATALOG!BK655) | BL7: =IF(DATALOG!BL655=0,"",DATALOG!BL655)
C8: =IF(DATALOG!C656=0,"",DATALOG!C656) -> 12 | D8: =IF(DATALOG!D656=0,"",DATALOG!D656) -> 8800 | E8: =IF(DATALOG!E656=0,"",DATALOG!E656) -> 13 | F8: =IF(DATALOG!F656=0,"",DATALOG!F656) -> 6217 | G8: =IF(DATALOG!G656=0,"",DATALOG!G656) -> 9 | H8: =IF(DATALOG!H656=0,"",DATALOG!H656) -> 8437 | I8: =IF(DATALOG!I656=0,"",DATALOG!I656) | J8: =IF(DATALOG!J656=0,"",DATALOG!J656) -> 10 | ... O8: =IF(DATALOG!O656=0,"",DATALOG!O656) -> 9000 | Q8: =IF(DATALOG!Q656=0,"",DATALOG!Q656) -> 14 | R8: =IF(DATALOG!R656=0,"",DATALOG!R656) -> 10143 | S8: =IF(DATALOG!S656=0,"",DATALOG!S656) -> 11 | T8: =IF(DATALOG!T656=0,"",DATALOG!T656) -> 5321 | U8: =IF(DATALOG!U656=0,"",DATALOG!U656) -> 12 | V8: =IF(DATALOG!V656=0,"",DATALOG!V656) -> 4000 | X8: =IF(DATALOG!X656=0,"",DATALOG!X656) -> 15 | Y8: =IF(DATALOG!Y656=0,"",DATALOG!Y656) -> 2000 | Z8: =IF(DATALOG!Z656=0,"",DATALOG!Z656) -> 10 | AA8: =IF(DATALOG!AA656=0,"",DATALOG!AA656) -> 1650 | AB8: =IF(DATALOG!AB656=0,"",DATALOG!AB656) -> 11 | AC8: =IF(DATALOG!AC656=0,"",DATALOG!AC656) -> 5800 | AE8: =IF(DATALOG!AE656=0,"",DATALOG!AE656) -> 10 | AF8: =IF(DATALOG!AF656=0,"",DATALOG!AF656) -> 5926 | AG8: =IF(DATALOG!AG656=0,"",DATALOG!AG656) -> 9 | AH8: =IF(DATALOG!AH656=0,"",DATALOG!AH656) -> 9365 | AI8: =IF(DATALOG!AI656=0,"",DATALOG!AI656) -> 8 | AJ8: =IF(DATALOG!AJ656=0,"",DATALOG!AJ656) -> 11250 | AL8: =IF(DATALOG!AL656=0,"",DATALOG!AL656) -> 13 | AM8: =IF(DATALOG!AM656=0,"",DATALOG!AM656) -> 757 | AN8: =IF(DATALOG!AN656=0,"",DATALOG!AN656) -> 9 | AO8: =IF(DATALOG!AO656=0,"",DATALOG!AO656) -> 15608 | AP8: =IF(DATALOG!AP656=0,"",DATALOG!AP656) -> 16 | AQ8: =IF(DATALOG!AQ656=0,"",DATALOG!AQ656) -> 6500 | AS8: =IF(DATALOG!AS656=0,"",DATALOG!AS656) -> 15 | AT8: =IF(DATALOG!AT656=0,"",DATALOG!AT656) -> 3000 | AU8: =IF(DATALOG!AU656=0,"",DATALOG!AU656) -> 11 | AV8: =IF(DATALOG!AV656=0,"",DATALOG!AV656) -> 3790 | AW8: =IF(DATALOG!AW656=0,"",DATALOG!AW656) -> 11 | AX8: =IF(DATALOG!AX656=0,"",DATALOG!AX656) -> 4105 | AZ8: =IF(DATALOG!AZ656=0,"",DATALOG!AZ656) | BA8: =IF(DATALOG!BA656=0,"",DATALOG!BA656) | BB8: =IF(DATALOG!BB656=0,"",DATALOG!BB656) | BC8: =IF(DATALOG!BC656=0,"",DATALOG!BC656) | BD8: =IF(DATALOG!BD656=0,"",DATALOG!BD656) | BE8: =IF(DATALOG!BE656=0,"",DATALOG!BE656) | BG8: =IF(DATALOG!BG656=0,"",DATALOG!BG656) | BH8: =IF(DATALOG!BH656=0,"",DATALOG!BH656) | BI8: =IF(DATALOG!BI656=0,"",DATALOG!BI656) | BJ8: =IF(DATALOG!BJ656=0,"",DATALOG!BJ656) | BK8: =IF(DATALOG!BK656=0,"",DATALOG!BK656) | BL8: =IF(DATALOG!BL656=0,"",DATALOG!BL656)
C9: =IF(DATALOG!C657=0,"",DATALOG!C657) -> 14 | D9: =IF(DATALOG!D657=0,"",DATALOG!D657) -> 9000 | E9: =IF(DATALOG!E657=0,"",DATALOG!E657) -> 14 | F9: =IF(DATALOG!F657=0,"",DATALOG!F657) -> 4200 | G9: =IF(DATALOG!G657=0,"",DATALOG!G657) -> 10 | H9: =IF(DATALOG!H657=0,"",DATALOG!H657) -> 5100 | I9: =IF(DATALOG!I657=0,"",DATALOG!I657) | J9: =IF(DATALOG!J657=0,"",DATALOG!J657) -> 12 | ... O9: =IF(DATALOG!O657=0,"",DATALOG!O657) -> 6750 | Q9: =IF(DATALOG!Q657=0,"",DATALOG!Q657) -> 15 | R9: =IF(DATALOG!R657=0,"",DATALOG!R657) -> 3000 | S9: =IF(DATALOG!S657=0,"",DATALOG!S657) -> 12 | T9: =IF(DATALOG!T657=0,"",DATALOG!T657) -> 6752 | U9: =IF(DATALOG!U657=0,"",DATALOG!U657) -> 13 | V9: =IF(DATALOG!V657=0,"",DATALOG!V657) -> 7572 | X9: =IF(DATALOG!X657=0,"",DATALOG!X657) -> 16 | Y9: =IF(DATALOG!Y657=0,"",DATALOG!Y657) -> 6000 | Z9: =IF(DATALOG!Z657=0,"",DATALOG!Z657) -> 11 | AA9: =IF(DATALOG!AA657=0,"",DATALOG!AA657) -> 6735 | AB9: =IF(DATALOG!AB657=0,"",DATALOG!AB657) -> 12 | AC9: =IF(DATALOG!AC657=0,"",DATALOG!AC657) -> 4000 | AE9: =IF(DATALOG!AE657=0,"",DATALOG!AE657) -> 12 | AF9: =IF(DATALOG!AF657=0,"",DATALOG!AF657) -> 7493 | AG9: =IF(DATALOG!AG657=0,"",DATALOG!AG657) -> 10 | AH9: =IF(DATALOG!AH657=0,"",DATALOG!AH657) -> 1250 | AI9: =IF(DATALOG!AI657=0,"",DATALOG!AI657) -> 9 | AJ9: =IF(DATALOG!AJ657=0,"",DATALOG!AJ657) -> 11250 | AL9: =IF(DATALOG!AL657=0,"",DATALOG!AL657) -> 15 | AM9: =IF(DATALOG!AM657=0,"",DATALOG!AM657) -> 3000 | AN9: =IF(DATALOG!AN657=0,"",DATALOG!AN657) -> 11 | AO9: =IF(DATALOG!AO657=0,"",DATALOG!AO657) -> 4000 | AP9: =IF(DATALOG!AP657=0,"",DATALOG!AP657) -> 17 | AQ9: =IF(DATALOG!AQ657=0,"",DATALOG!AQ657) -> 2138 | AS9: =IF(DATALOG!AS657=0,"",DATALOG!AS657) -> 16 | AT9: =IF(DATALOG!AT657=0,"",DATALOG!AT657) -> 4709 | AU9: =IF(DATALOG!AU657=0,"",DATALOG!AU657) -> 12 | AV9: =IF(DATALOG!AV657=0,"",DATALOG!AV657) -> 5000 | AW9: =IF(DATALOG!AW657=0,"",DATALOG!AW657) -> 13 | AX9: =IF(DATALOG!AX657=0,"",DATALOG!AX657) -> 5300 | AZ9: =IF(DATALOG!AZ657=0,"",DATALOG!AZ657) | BA9: =IF(DATALOG!BA657=0,"",DATALOG!BA657) | BB9: =IF(DATALOG!BB657=0,"",DATALOG!BB657) | BC9: =IF(DATALOG!BC657=0,"",DATALOG!BC657) | BD9: =IF(DATALOG!BD657=0,"",DATALOG!BD657) | BE9: =IF(DATALOG!BE657=0,"",DATALOG!BE657) | BG9: =IF(DATALOG!BG657=0,"",DATALOG!BG657) | BH9: =IF(DATALOG!BH657=0,"",DATALOG!BH657) | BI9: =IF(DATALOG!BI657=0,"",DATALOG!BI657) | BJ9: =IF(DATALOG!BJ657=0,"",DATALOG!BJ657) | BK9: =IF(DATALOG!BK657=0,"",DATALOG!BK657) | BL9: =IF(DATALOG!BL657=0,"",DATALOG!BL657)
C10: =IF(DATALOG!C658=0,"",DATALOG!C658) -> 15 | D10: =IF(DATALOG!D658=0,"",DATALOG!D658) -> 19574 | E10: =IF(DATALOG!E658=0,"",DATALOG!E658) -> 16 | F10: =IF(DATALOG!F658=0,"",DATALOG!F658) -> 4000 | G10: =IF(DATALOG!G658=0,"",DATALOG!G658) -> 11 | H10: =IF(DATALOG!H658=0,"",DATALOG!H658) -> 4001 | I10: =IF(DATALOG!I658=0,"",DATALOG!I658) | J10: =IF(DATALOG!J658=0,"",DATALOG!J658) -> 14 | ... O10: =IF(DATALOG!O658=0,"",DATALOG!O658) -> 6280 | Q10: =IF(DATALOG!Q658=0,"",DATALOG!Q658) -> 16 | R10: =IF(DATALOG!R658=0,"",DATALOG!R658) -> 6000 | S10: =IF(DATALOG!S658=0,"",DATALOG!S658) -> 13 | T10: =IF(DATALOG!T658=0,"",DATALOG!T658) -> 984 | U10: =IF(DATALOG!U658=0,"",DATALOG!U658) -> 15 | V10: =IF(DATALOG!V658=0,"",DATALOG!V658) -> 24107 | X10: =IF(DATALOG!X658=0,"",DATALOG!X658) -> 17 | Y10: =IF(DATALOG!Y658=0,"",DATALOG!Y658) -> 18002 | Z10: =IF(DATALOG!Z658=0,"",DATALOG!Z658) -> 12 | AA10: =IF(DATALOG!AA658=0,"",DATALOG!AA658) -> 6930 | AB10: =IF(DATALOG!AB658=0,"",DATALOG!AB658) -> 13 | AC10: =IF(DATALOG!AC658=0,"",DATALOG!AC658) -> 13500 | AE10: =IF(DATALOG!AE658=0,"",DATALOG!AE658) -> 13 | AF10: =IF(DATALOG!AF658=0,"",DATALOG!AF658) -> 5000 | AG10: =IF(DATALOG!AG658=0,"",DATALOG!AG658) -> 11 | AH10: =IF(DATALOG!AH658=0,"",DATALOG!AH658) -> 4782 | AI10: =IF(DATALOG!AI658=0,"",DATALOG!AI658) -> 10 | AJ10: =IF(DATALOG!AJ658=0,"",DATALOG!AJ658) -> 2800 | AL10: =IF(DATALOG!AL658=0,"",DATALOG!AL658) -> 16 | AM10: =IF(DATALOG!AM658=0,"",DATALOG!AM658) -> 4500 | AN10: =IF(DATALOG!AN658=0,"",DATALOG!AN658) -> 12 | AO10: =IF(DATALOG!AO658=0,"",DATALOG!AO658) -> 7000 | AP10: =IF(DATALOG!AP658=0,"",DATALOG!AP658) -> 20 | AQ10: =IF(DATALOG!AQ658=0,"",DATALOG!AQ658) -> 2797 | AS10: =IF(DATALOG!AS658=0,"",DATALOG!AS658) -> 17 | AT10: =IF(DATALOG!AT658=0,"",DATALOG!AT658) -> 10000 | AU10: =IF(DATALOG!AU658=0,"",DATALOG!AU658) -> 16 | AV10: =IF(DATALOG!AV658=0,"",DATALOG!AV658) -> 2800 | AW10: =IF(DATALOG!AW658=0,"",DATALOG!AW658) -> 16 | AX10: =IF(DATALOG!AX658=0,"",DATALOG!AX658) -> 1500 | AZ10: =IF(DATALOG!AZ658=0,"",DATALOG!AZ658) | BA10: =IF(DATALOG!BA658=0,"",DATALOG!BA658) | BB10: =IF(DATALOG!BB658=0,"",DATALOG!BB658) | BC10: =IF(DATALOG!BC658=0,"",DATALOG!BC658) | BD10: =IF(DATALOG!BD658=0,"",DATALOG!BD658) | BE10: =IF(DATALOG!BE658=0,"",DATALOG!BE658) | BG10: =IF(DATALOG!BG658=0,"",DATALOG!BG658) | BH10: =IF(DATALOG!BH658=0,"",DATALOG!BH658) | BI10: =IF(DATALOG!BI658=0,"",DATALOG!BI658) | BJ10: =IF(DATALOG!BJ658=0,"",DATALOG!BJ658) | BK10: =IF(DATALOG!BK658=0,"",DATALOG!BK658) | BL10: =IF(DATALOG!BL658=0,"",DATALOG!BL658)
C11: =IF(DATALOG!C659=0,"",DATALOG!C659) -> 16 | D11: =IF(DATALOG!D659=0,"",DATALOG!D659) -> 8125 | E11: =IF(DATALOG!E659=0,"",DATALOG!E659) -> 17 | F11: =IF(DATALOG!F659=0,"",DATALOG!F659) -> 3790 | G11: =IF(DATALOG!G659=0,"",DATALOG!G659) -> 12 | H11: =IF(DATALOG!H659=0,"",DATALOG!H659) -> 5250 | I11: =IF(DATALOG!I659=0,"",DATALOG!I659) | J11: =IF(DATALOG!J659=0,"",DATALOG!J659) -> 15 | ... O11: =IF(DATALOG!O659=0,"",DATALOG!O659) -> 4350 | Q11: =IF(DATALOG!Q659=0,"",DATALOG!Q659) -> 17 | R11: =IF(DATALOG!R659=0,"",DATALOG!R659) -> 20000 | S11: =IF(DATALOG!S659=0,"",DATALOG!S659) -> 14 | T11: =IF(DATALOG!T659=0,"",DATALOG!T659) -> 4770 | U11: =IF(DATALOG!U659=0,"",DATALOG!U659) -> 16 | V11: =IF(DATALOG!V659=0,"",DATALOG!V659) -> 3718 | X11: =IF(DATALOG!X659=0,"",DATALOG!X659) -> 18 | Y11: =IF(DATALOG!Y659=0,"",DATALOG!Y659) -> 3699 | Z11: =IF(DATALOG!Z659=0,"",DATALOG!Z659) -> 13 | AA11: =IF(DATALOG!AA659=0,"",DATALOG!AA659) -> 5129 | AB11: =IF(DATALOG!AB659=0,"",DATALOG!AB659) -> 14 | AC11: =IF(DATALOG!AC659=0,"",DATALOG!AC659) -> 8020 | AE11: =IF(DATALOG!AE659=0,"",DATALOG!AE659) -> 14 | AF11: =IF(DATALOG!AF659=0,"",DATALOG!AF659) -> 7100 | AG11: =IF(DATALOG!AG659=0,"",DATALOG!AG659) -> 12 | AH11: =IF(DATALOG!AH659=0,"",DATALOG!AH659) -> 6000 | AI11: =IF(DATALOG!AI659=0,"",DATALOG!AI659) -> 11 | AJ11: =IF(DATALOG!AJ659=0,"",DATALOG!AJ659) -> 5782 | AL11: =IF(DATALOG!AL659=0,"",DATALOG!AL659) -> 17 | AM11: =IF(DATALOG!AM659=0,"",DATALOG!AM659) -> 5000 | AN11: =IF(DATALOG!AN659=0,"",DATALOG!AN659) -> 16 | AO11: =IF(DATALOG!AO659=0,"",DATALOG!AO659) -> 2800 | AP11: =IF(DATALOG!AP659=0,"",DATALOG!AP659) -> 21 | AQ11: =IF(DATALOG!AQ659=0,"",DATALOG!AQ659) -> 8779 | AS11: =IF(DATALOG!AS659=0,"",DATALOG!AS659) -> 18 | AT11: =IF(DATALOG!AT659=0,"",DATALOG!AT659) -> 2666 | AU11: =IF(DATALOG!AU659=0,"",DATALOG!AU659) -> 38 | AV11: =IF(DATALOG!AV659=0,"",DATALOG!AV659) -> 11294 | AW11: =IF(DATALOG!AW659=0,"",DATALOG!AW659) -> 18 | AX11: =IF(DATALOG!AX659=0,"",DATALOG!AX659) -> 9000 | AZ11: =IF(DATALOG!AZ659=0,"",DATALOG!AZ659) | BA11: =IF(DATALOG!BA659=0,"",DATALOG!BA659) | BB11: =IF(DATALOG!BB659=0,"",DATALOG!BB659) | BC11: =IF(DATALOG!BC659=0,"",DATALOG!BC659) | BD11: =IF(DATALOG!BD659=0,"",DATALOG!BD659) | BE11: =IF(DATALOG!BE659=0,"",DATALOG!BE659) | BG11: =IF(DATALOG!BG659=0,"",DATALOG!BG659) | BH11: =IF(DATALOG!BH659=0,"",DATALOG!BH659) | BI11: =IF(DATALOG!BI659=0,"",DATALOG!BI659) | BJ11: =IF(DATALOG!BJ659=0,"",DATALOG!BJ659) | BK11: =IF(DATALOG!BK659=0,"",DATALOG!BK659) | BL11: =IF(DATALOG!BL659=0,"",DATALOG!BL659)
C12: =IF(DATALOG!C660=0,"",DATALOG!C660) -> 17 | D12: =IF(DATALOG!D660=0,"",DATALOG!D660) -> 8001 | E12: =IF(DATALOG!E660=0,"",DATALOG!E660) -> 18 | F12: =IF(DATALOG!F660=0,"",DATALOG!F660) -> 1500 | G12: =IF(DATALOG!G660=0,"",DATALOG!G660) -> 13 | H12: =IF(DATALOG!H660=0,"",DATALOG!H660) -> 4000 | I12: =IF(DATALOG!I660=0,"",DATALOG!I660) | J12: =IF(DATALOG!J660=0,"",DATALOG!J660) -> 16 | ... O12: =IF(DATALOG!O660=0,"",DATALOG!O660) -> 5400 | Q12: =IF(DATALOG!Q660=0,"",DATALOG!Q660) -> 18 | R12: =IF(DATALOG!R660=0,"",DATALOG!R660) -> 7851 | S12: =IF(DATALOG!S660=0,"",DATALOG!S660) -> 16 | T12: =IF(DATALOG!T660=0,"",DATALOG!T660) -> 6822 | U12: =IF(DATALOG!U660=0,"",DATALOG!U660) -> 17 | V12: =IF(DATALOG!V660=0,"",DATALOG!V660) -> 1525 | X12: =IF(DATALOG!X660=0,"",DATALOG!X660) -> 19 | Y12: =IF(DATALOG!Y660=0,"",DATALOG!Y660) -> 3300 | Z12: =IF(DATALOG!Z660=0,"",DATALOG!Z660) -> 14 | AA12: =IF(DATALOG!AA660=0,"",DATALOG!AA660) -> 5601 | AB12: =IF(DATALOG!AB660=0,"",DATALOG!AB660) -> 15 | AC12: =IF(DATALOG!AC660=0,"",DATALOG!AC660) -> 16875 | AE12: =IF(DATALOG!AE660=0,"",DATALOG!AE660) -> 15 | AF12: =IF(DATALOG!AF660=0,"",DATALOG!AF660) -> 7299 | AG12: =IF(DATALOG!AG660=0,"",DATALOG!AG660) -> 13 | AH12: =IF(DATALOG!AH660=0,"",DATALOG!AH660) -> 5329 | AI12: =IF(DATALOG!AI660=0,"",DATALOG!AI660) -> 12 | AJ12: =IF(DATALOG!AJ660=0,"",DATALOG!AJ660) -> 6200 | AL12: =IF(DATALOG!AL660=0,"",DATALOG!AL660) -> 18 | AM12: =IF(DATALOG!AM660=0,"",DATALOG!AM660) -> 5397 | AN12: =IF(DATALOG!AN660=0,"",DATALOG!AN660) -> 21 | AO12: =IF(DATALOG!AO660=0,"",DATALOG!AO660) -> 7500 | AP12: =IF(DATALOG!AP660=0,"",DATALOG!AP660) -> 22 | AQ12: =IF(DATALOG!AQ660=0,"",DATALOG!AQ660) -> 15000 | AS12: =IF(DATALOG!AS660=0,"",DATALOG!AS660) -> 19 | AT12: =IF(DATALOG!AT660=0,"",DATALOG!AT660) -> 3000 | AU12: =IF(DATALOG!AU660=0,"",DATALOG!AU660) -> 39 | AV12: =IF(DATALOG!AV660=0,"",DATALOG!AV660) -> 8600 | AW12: =IF(DATALOG!AW660=0,"",DATALOG!AW660) -> 19 | AX12: =IF(DATALOG!AX660=0,"",DATALOG!AX660) -> 11250 | AZ12: =IF(DATALOG!AZ660=0,"",DATALOG!AZ660) | BA12: =IF(DATALOG!BA660=0,"",DATALOG!BA660) | BB12: =IF(DATALOG!BB660=0,"",DATALOG!BB660) | BC12: =IF(DATALOG!BC660=0,"",DATALOG!BC660) | BD12: =IF(DATALOG!BD660=0,"",DATALOG!BD660) | BE12: =IF(DATALOG!BE660=0,"",DATALOG!BE660) | BG12: =IF(DATALOG!BG660=0,"",DATALOG!BG660) | BH12: =IF(DATALOG!BH660=0,"",DATALOG!BH660) | BI12: =IF(DATALOG!BI660=0,"",DATALOG!BI660) | BJ12: =IF(DATALOG!BJ660=0,"",DATALOG!BJ660) | BK12: =IF(DATALOG!BK660=0,"",DATALOG!BK660) | BL12: =IF(DATALOG!BL660=0,"",DATALOG!BL660)
C13: =IF(DATALOG!C661=0,"",DATALOG!C661) -> 18 | D13: =IF(DATALOG!D661=0,"",DATALOG!D661) -> 3699 | E13: =IF(DATALOG!E661=0,"",DATALOG!E661) -> 20 | F13: =IF(DATALOG!F661=0,"",DATALOG!F661) -> 6788 | G13: =IF(DATALOG!G661=0,"",DATALOG!G661) -> 14 | H13: =IF(DATALOG!H661=0,"",DATALOG!H661) -> 10125 | I13: =IF(DATALOG!I661=0,"",DATALOG!I661) | J13: =IF(DATALOG!J661=0,"",DATALOG!J661) -> 17 | ... O13: =IF(DATALOG!O661=0,"",DATALOG!O661) -> 8100 | Q13: =IF(DATALOG!Q661=0,"",DATALOG!Q661) -> 19 | R13: =IF(DATALOG!R661=0,"",DATALOG!R661) -> 3149 | S13: =IF(DATALOG!S661=0,"",DATALOG!S661) -> 17 | T13: =IF(DATALOG!T661=0,"",DATALOG!T661) -> 1911 | U13: =IF(DATALOG!U661=0,"",DATALOG!U661) -> 18 | V13: =IF(DATALOG!V661=0,"",DATALOG!V661) -> 13287 | X13: =IF(DATALOG!X661=0,"",DATALOG!X661) -> 21 | Y13: =IF(DATALOG!Y661=0,"",DATALOG!Y661) -> 12001 | Z13: =IF(DATALOG!Z661=0,"",DATALOG!Z661) -> 15 | AA13: =IF(DATALOG!AA661=0,"",DATALOG!AA661) -> 15000 | AB13: =IF(DATALOG!AB661=0,"",DATALOG!AB661) -> 16 | AC13: =IF(DATALOG!AC661=0,"",DATALOG!AC661) -> 1500 | AE13: =IF(DATALOG!AE661=0,"",DATALOG!AE661) -> 16 | AF13: =IF(DATALOG!AF661=0,"",DATALOG!AF661) -> 5500 | AG13: =IF(DATALOG!AG661=0,"",DATALOG!AG661) -> 14 | AH13: =IF(DATALOG!AH661=0,"",DATALOG!AH661) -> 7580 | AI13: =IF(DATALOG!AI661=0,"",DATALOG!AI661) -> 13 | AJ13: =IF(DATALOG!AJ661=0,"",DATALOG!AJ661) -> 4620 | AL13: =IF(DATALOG!AL661=0,"",DATALOG!AL661) -> 20 | AM13: =IF(DATALOG!AM661=0,"",DATALOG!AM661) -> 10000 | AN13: =IF(DATALOG!AN661=0,"",DATALOG!AN661) -> 22 | AO13: =IF(DATALOG!AO661=0,"",DATALOG!AO661) -> 13765 | AP13: =IF(DATALOG!AP661=0,"",DATALOG!AP661) -> 23 | AQ13: =IF(DATALOG!AQ661=0,"",DATALOG!AQ661) -> 4120 | AS13: =IF(DATALOG!AS661=0,"",DATALOG!AS661) -> 20 | AT13: =IF(DATALOG!AT661=0,"",DATALOG!AT661) -> 15000 | AU13: =IF(DATALOG!AU661=0,"",DATALOG!AU661) -> 53 | AV13: =IF(DATALOG!AV661=0,"",DATALOG!AV661) -> 3570 | AW13: =IF(DATALOG!AW661=0,"",DATALOG!AW661) -> 20 | AX13: =IF(DATALOG!AX661=0,"",DATALOG!AX661) -> 4173 | AZ13: =IF(DATALOG!AZ661=0,"",DATALOG!AZ661) | BA13: =IF(DATALOG!BA661=0,"",DATALOG!BA661) | BB13: =IF(DATALOG!BB661=0,"",DATALOG!BB661) | BC13: =IF(DATALOG!BC661=0,"",DATALOG!BC661) | BD13: =IF(DATALOG!BD661=0,"",DATALOG!BD661) | BE13: =IF(DATALOG!BE661=0,"",DATALOG!BE661) | BG13: =IF(DATALOG!BG661=0,"",DATALOG!BG661) | BH13: =IF(DATALOG!BH661=0,"",DATALOG!BH661) | BI13: =IF(DATALOG!BI661=0,"",DATALOG!BI661) | BJ13: =IF(DATALOG!BJ661=0,"",DATALOG!BJ661) | BK13: =IF(DATALOG!BK661=0,"",DATALOG!BK661) | BL13: =IF(DATALOG!BL661=0,"",DATALOG!BL661)
C14: =IF(DATALOG!C662=0,"",DATALOG!C662) -> 19 | D14: =IF(DATALOG!D662=0,"",DATALOG!D662) -> 10624 | E14: =IF(DATALOG!E662=0,"",DATALOG!E662) -> 21 | F14: =IF(DATALOG!F662=0,"",DATALOG!F662) -> 1000 | G14: =IF(DATALOG!G662=0,"",DATALOG!G662) -> 16 | H14: =IF(DATALOG!H662=0,"",DATALOG!H662) -> 2500 | I14: =IF(DATALOG!I662=0,"",DATALOG!I662) | J14: =IF(DATALOG!J662=0,"",DATALOG!J662) -> 18 | ... O14: =IF(DATALOG!O662=0,"",DATALOG!O662) -> 2500 | Q14: =IF(DATALOG!Q662=0,"",DATALOG!Q662) -> 24 | R14: =IF(DATALOG!R662=0,"",DATALOG!R662) -> 8736 | S14: =IF(DATALOG!S662=0,"",DATALOG!S662) -> 18 | T14: =IF(DATALOG!T662=0,"",DATALOG!T662) -> 5512 | U14: =IF(DATALOG!U662=0,"",DATALOG!U662) -> 19 | V14: =IF(DATALOG!V662=0,"",DATALOG!V662) -> 19286 | X14: =IF(DATALOG!X662=0,"",DATALOG!X662) -> 23 | Y14: =IF(DATALOG!Y662=0,"",DATALOG!Y662) -> 7098 | Z14: =IF(DATALOG!Z662=0,"",DATALOG!Z662) -> 16 | AA14: =IF(DATALOG!AA662=0,"",DATALOG!AA662) -> 6775 | AB14: =IF(DATALOG!AB662=0,"",DATALOG!AB662) -> 17 | AC14: =IF(DATALOG!AC662=0,"",DATALOG!AC662) -> 1742 | AE14: =IF(DATALOG!AE662=0,"",DATALOG!AE662) -> 17 | AF14: =IF(DATALOG!AF662=0,"",DATALOG!AF662) -> 5000 | AG14: =IF(DATALOG!AG662=0,"",DATALOG!AG662) -> 16 | AH14: =IF(DATALOG!AH662=0,"",DATALOG!AH662) -> 4100 | AI14: =IF(DATALOG!AI662=0,"",DATALOG!AI662) -> 14 | AJ14: =IF(DATALOG!AJ662=0,"",DATALOG!AJ662) -> 8020 | AL14: =IF(DATALOG!AL662=0,"",DATALOG!AL662) -> 23 | AM14: =IF(DATALOG!AM662=0,"",DATALOG!AM662) -> 7683 | AN14: =IF(DATALOG!AN662=0,"",DATALOG!AN662) -> 30 | AO14: =IF(DATALOG!AO662=0,"",DATALOG!AO662) -> 4865 | AP14: =IF(DATALOG!AP662=0,"",DATALOG!AP662) -> 31 | AQ14: =IF(DATALOG!AQ662=0,"",DATALOG!AQ662) -> 4519 | AS14: =IF(DATALOG!AS662=0,"",DATALOG!AS662) -> 65 | AT14: =IF(DATALOG!AT662=0,"",DATALOG!AT662) -> 4000 | AU14: =IF(DATALOG!AU662=0,"",DATALOG!AU662) -> 66 | AV14: =IF(DATALOG!AV662=0,"",DATALOG!AV662) -> 3358 | AW14: =IF(DATALOG!AW662=0,"",DATALOG!AW662) -> 23 | AX14: =IF(DATALOG!AX662=0,"",DATALOG!AX662) -> 3250 | AZ14: =IF(DATALOG!AZ662=0,"",DATALOG!AZ662) | BA14: =IF(DATALOG!BA662=0,"",DATALOG!BA662) | BB14: =IF(DATALOG!BB662=0,"",DATALOG!BB662) | BC14: =IF(DATALOG!BC662=0,"",DATALOG!BC662) | BD14: =IF(DATALOG!BD662=0,"",DATALOG!BD662) | BE14: =IF(DATALOG!BE662=0,"",DATALOG!BE662) | BG14: =IF(DATALOG!BG662=0,"",DATALOG!BG662) | BH14: =IF(DATALOG!BH662=0,"",DATALOG!BH662) | BI14: =IF(DATALOG!BI662=0,"",DATALOG!BI662) | BJ14: =IF(DATALOG!BJ662=0,"",DATALOG!BJ662) | BK14: =IF(DATALOG!BK662=0,"",DATALOG!BK662) | BL14: =IF(DATALOG!BL662=0,"",DATALOG!BL662)
C15: =IF(DATALOG!C663=0,"",DATALOG!C663) -> 20 | D15: =IF(DATALOG!D663=0,"",DATALOG!D663) -> 9000 | E15: =IF(DATALOG!E663=0,"",DATALOG!E663) -> 22 | F15: =IF(DATALOG!F663=0,"",DATALOG!F663) -> 2437 | G15: =IF(DATALOG!G663=0,"",DATALOG!G663) -> 17 | H15: =IF(DATALOG!H663=0,"",DATALOG!H663) -> 9779 | I15: =IF(DATALOG!I663=0,"",DATALOG!I663) | J15: =IF(DATALOG!J663=0,"",DATALOG!J663) -> 19 | ... O15: =IF(DATALOG!O663=0,"",DATALOG!O663) -> 8511 | Q15: =IF(DATALOG!Q663=0,"",DATALOG!Q663) -> 27 | R15: =IF(DATALOG!R663=0,"",DATALOG!R663) -> 2545 | S15: =IF(DATALOG!S663=0,"",DATALOG!S663) -> 19 | T15: =IF(DATALOG!T663=0,"",DATALOG!T663) -> 21428 | U15: =IF(DATALOG!U663=0,"",DATALOG!U663) -> 20 | V15: =IF(DATALOG!V663=0,"",DATALOG!V663) -> 11257 | X15: =IF(DATALOG!X663=0,"",DATALOG!X663) -> 28 | Y15: =IF(DATALOG!Y663=0,"",DATALOG!Y663) -> 14523 | Z15: =IF(DATALOG!Z663=0,"",DATALOG!Z663) -> 17 | AA15: =IF(DATALOG!AA663=0,"",DATALOG!AA663) -> 2615 | AB15: =IF(DATALOG!AB663=0,"",DATALOG!AB663) -> 20 | AC15: =IF(DATALOG!AC663=0,"",DATALOG!AC663) -> 10000 | AE15: =IF(DATALOG!AE663=0,"",DATALOG!AE663) -> 18 | AF15: =IF(DATALOG!AF663=0,"",DATALOG!AF663) -> 2704 | AG15: =IF(DATALOG!AG663=0,"",DATALOG!AG663) -> 17 | AH15: =IF(DATALOG!AH663=0,"",DATALOG!AH663) -> 5778 | AI15: =IF(DATALOG!AI663=0,"",DATALOG!AI663) -> 15 | AJ15: =IF(DATALOG!AJ663=0,"",DATALOG!AJ663) -> 11250 | AL15: =IF(DATALOG!AL663=0,"",DATALOG!AL663) -> 27 | AM15: =IF(DATALOG!AM663=0,"",DATALOG!AM663) -> 4168 | AN15: =IF(DATALOG!AN663=0,"",DATALOG!AN663) -> 31 | AO15: =IF(DATALOG!AO663=0,"",DATALOG!AO663) -> 10 | AP15: =IF(DATALOG!AP663=0,"",DATALOG!AP663) -> 32 | AQ15: =IF(DATALOG!AQ663=0,"",DATALOG!AQ663) -> 6000 | AS15: =IF(DATALOG!AS663=0,"",DATALOG!AS663) -> 66 | AT15: =IF(DATALOG!AT663=0,"",DATALOG!AT663) -> 14250 | AU15: =IF(DATALOG!AU663=0,"",DATALOG!AU663) -> 67 | AV15: =IF(DATALOG!AV663=0,"",DATALOG!AV663) -> 5237 | AW15: =IF(DATALOG!AW663=0,"",DATALOG!AW663) -> 35 | AX15: =IF(DATALOG!AX663=0,"",DATALOG!AX663) -> 11334 | AZ15: =IF(DATALOG!AZ663=0,"",DATALOG!AZ663) | BA15: =IF(DATALOG!BA663=0,"",DATALOG!BA663) | BB15: =IF(DATALOG!BB663=0,"",DATALOG!BB663) | BC15: =IF(DATALOG!BC663=0,"",DATALOG!BC663) | BD15: =IF(DATALOG!BD663=0,"",DATALOG!BD663) | BE15: =IF(DATALOG!BE663=0,"",DATALOG!BE663) | BG15: =IF(DATALOG!BG663=0,"",DATALOG!BG663) | BH15: =IF(DATALOG!BH663=0,"",DATALOG!BH663) | BI15: =IF(DATALOG!BI663=0,"",DATALOG!BI663) | BJ15: =IF(DATALOG!BJ663=0,"",DATALOG!BJ663) | BK15: =IF(DATALOG!BK663=0,"",DATALOG!BK663) | BL15: =IF(DATALOG!BL663=0,"",DATALOG!BL663)
C16: =IF(DATALOG!C664=0,"",DATALOG!C664) -> 21 | D16: =IF(DATALOG!D664=0,"",DATALOG!D664) -> 13375 | E16: =IF(DATALOG!E664=0,"",DATALOG!E664) -> 29 | F16: =IF(DATALOG!F664=0,"",DATALOG!F664) -> 13125 | G16: =IF(DATALOG!G664=0,"",DATALOG!G664) -> 18 | H16: =IF(DATALOG!H664=0,"",DATALOG!H664) -> 8437 | I16: =IF(DATALOG!I664=0,"",DATALOG!I664) | J16: =IF(DATALOG!J664=0,"",DATALOG!J664) -> 23 | ... O16: =IF(DATALOG!O664=0,"",DATALOG!O664) -> 6750 | Q16: =IF(DATALOG!Q664=0,"",DATALOG!Q664) -> 32 | R16: =IF(DATALOG!R664=0,"",DATALOG!R664) -> 33962 | S16: =IF(DATALOG!S664=0,"",DATALOG!S664) -> 20 | T16: =IF(DATALOG!T664=0,"",DATALOG!T664) -> 12428 | U16: =IF(DATALOG!U664=0,"",DATALOG!U664) -> 23 | V16: =IF(DATALOG!V664=0,"",DATALOG!V664) -> 5715 | X16: =IF(DATALOG!X664=0,"",DATALOG!X664) -> 33 | Y16: =IF(DATALOG!Y664=0,"",DATALOG!Y664) -> 3500 | Z16: =IF(DATALOG!Z664=0,"",DATALOG!Z664) -> 18 | AA16: =IF(DATALOG!AA664=0,"",DATALOG!AA664) -> 6163 | AB16: =IF(DATALOG!AB664=0,"",DATALOG!AB664) -> 21 | AC16: =IF(DATALOG!AC664=0,"",DATALOG!AC664) -> 2741 | AE16: =IF(DATALOG!AE664=0,"",DATALOG!AE664) -> 19 | AF16: =IF(DATALOG!AF664=0,"",DATALOG!AF664) -> 2000 | AG16: =IF(DATALOG!AG664=0,"",DATALOG!AG664) -> 18 | AH16: =IF(DATALOG!AH664=0,"",DATALOG!AH664) -> 7567 | AI16: =IF(DATALOG!AI664=0,"",DATALOG!AI664) -> 16 | AJ16: =IF(DATALOG!AJ664=0,"",DATALOG!AJ664) -> 1897 | AL16: =IF(DATALOG!AL664=0,"",DATALOG!AL664) -> 28 | AM16: =IF(DATALOG!AM664=0,"",DATALOG!AM664) -> 11129 | AN16: =IF(DATALOG!AN664=0,"",DATALOG!AN664) -> 34 | AO16: =IF(DATALOG!AO664=0,"",DATALOG!AO664) -> 7500 | AP16: =IF(DATALOG!AP664=0,"",DATALOG!AP664) -> 35 | AQ16: =IF(DATALOG!AQ664=0,"",DATALOG!AQ664) -> 5671 | AS16: =IF(DATALOG!AS664=0,"",DATALOG!AS664) -> 68 | AT16: =IF(DATALOG!AT664=0,"",DATALOG!AT664) -> 9703 | AU16: =IF(DATALOG!AU664=0,"",DATALOG!AU664) -> 68 | AV16: =IF(DATALOG!AV664=0,"",DATALOG!AV664) -> 6000 | AW16: =IF(DATALOG!AW664=0,"",DATALOG!AW664) -> 46 | AX16: =IF(DATALOG!AX664=0,"",DATALOG!AX664) -> 1546 | AZ16: =IF(DATALOG!AZ664=0,"",DATALOG!AZ664) | BA16: =IF(DATALOG!BA664=0,"",DATALOG!BA664) | BB16: =IF(DATALOG!BB664=0,"",DATALOG!BB664) | BC16: =IF(DATALOG!BC664=0,"",DATALOG!BC664) | BD16: =IF(DATALOG!BD664=0,"",DATALOG!BD664) | BE16: =IF(DATALOG!BE664=0,"",DATALOG!BE664) | BG16: =IF(DATALOG!BG664=0,"",DATALOG!BG664) | BH16: =IF(DATALOG!BH664=0,"",DATALOG!BH664) | BI16: =IF(DATALOG!BI664=0,"",DATALOG!BI664) | BJ16: =IF(DATALOG!BJ664=0,"",DATALOG!BJ664) | BK16: =IF(DATALOG!BK664=0,"",DATALOG!BK664) | BL16: =IF(DATALOG!BL664=0,"",DATALOG!BL664)
... C1003: =IF(DATALOG!C1651=0,"",DATALOG!C1651) | D1003: =IF(DATALOG!D1651=0,"",DATALOG!D1651) | E1003: =IF(DATALOG!E1651=0,"",DATALOG!E1651) | F1003: =IF(DATALOG!F1651=0,"",DATALOG!F1651) | G1003: =IF(DATALOG!G1651=0,"",DATALOG!G1651) | H1003: =IF(DATALOG!H1651=0,"",DATALOG!H1651) | I1003: =IF(DATALOG!I1651=0,"",DATALOG!I1651) | J1003: =IF(DATALOG!J1651=0,"",DATALOG!J1651) | ... O1003: =IF(DATALOG!O1651=0,"",DATALOG!O1651) | Q1003: =IF(DATALOG!Q1651=0,"",DATALOG!Q1651) | R1003: =IF(DATALOG!R1651=0,"",DATALOG!R1651) | S1003: =IF(DATALOG!S1651=0,"",DATALOG!S1651) | T1003: =IF(DATALOG!T1651=0,"",DATALOG!T1651) | U1003: =IF(DATALOG!U1651=0,"",DATALOG!U1651) | V1003: =IF(DATALOG!V1651=0,"",DATALOG!V1651) | X1003: =IF(DATALOG!X1651=0,"",DATALOG!X1651) | Y1003: =IF(DATALOG!Y1651=0,"",DATALOG!Y1651) | Z1003: =IF(DATALOG!Z1651=0,"",DATALOG!Z1651) | AA1003: =IF(DATALOG!AA1651=0,"",DATALOG!AA1651) | AB1003: =IF(DATALOG!AB1651=0,"",DATALOG!AB1651) | AC1003: =IF(DATALOG!AC1651=0,"",DATALOG!AC1651) | AE1003: =IF(DATALOG!AE1651=0,"",DATALOG!AE1651) | AF1003: =IF(DATALOG!AF1651=0,"",DATALOG!AF1651) | AG1003: =IF(DATALOG!AG1651=0,"",DATALOG!AG1651) | AH1003: =IF(DATALOG!AH1651=0,"",DATALOG!AH1651) | AI1003: =IF(DATALOG!AI1651=0,"",DATALOG!AI1651) | AJ1003: =IF(DATALOG!AJ1651=0,"",DATALOG!AJ1651) | AL1003: =IF(DATALOG!AL1651=0,"",DATALOG!AL1651) | AM1003: =IF(DATALOG!AM1651=0,"",DATALOG!AM1651) | AN1003: =IF(DATALOG!AN1651=0,"",DATALOG!AN1651) | AO1003: =IF(DATALOG!AO1651=0,"",DATALOG!AO1651) | AP1003: =IF(DATALOG!AP1651=0,"",DATALOG!AP1651) | AQ1003: =IF(DATALOG!AQ1651=0,"",DATALOG!AQ1651) | AS1003: =IF(DATALOG!AS1651=0,"",DATALOG!AS1651) | AT1003: =IF(DATALOG!AT1651=0,"",DATALOG!AT1651) | AU1003: =IF(DATALOG!AU1651=0,"",DATALOG!AU1651) | AV1003: =IF(DATALOG!AV1651=0,"",DATALOG!AV1651) | AW1003: =IF(DATALOG!AW1651=0,"",DATALOG!AW1651) | AX1003: =IF(DATALOG!AX1651=0,"",DATALOG!AX1651) | AZ1003: =IF(DATALOG!AZ1651=0,"",DATALOG!AZ1651) | BA1003: =IF(DATALOG!BA1651=0,"",DATALOG!BA1651) | BB1003: =IF(DATALOG!BB1651=0,"",DATALOG!BB1651) | BC1003: =IF(DATALOG!BC1651=0,"",DATALOG!BC1651) | BD1003: =IF(DATALOG!BD1651=0,"",DATALOG!BD1651) | BE1003: =IF(DATALOG!BE1651=0,"",DATALOG!BE1651) | BG1003: =IF(DATALOG!BG1651=0,"",DATALOG!BG1651) | BH1003: =IF(DATALOG!BH1651=0,"",DATALOG!BH1651) | BI1003: =IF(DATALOG!BI1651=0,"",DATALOG!BI1651) | BJ1003: =IF(DATALOG!BJ1651=0,"",DATALOG!BJ1651) | BK1003: =IF(DATALOG!BK1651=0,"",DATALOG!BK1651) | BL1003: =IF(DATALOG!BL1651=0,"",DATALOG!BL1651)

Sheet Inventario Empresas Linea 2
C2: =UPPER(DATALOG!B1652) -> EMPRESAS CON INVENTARIO ELECTRODOMES
C3: =IF(DATALOG!C1652="","",DATALOG!C1652) -> Alemania | D3: =IF(DATALOG!D1652="","",DATALOG!D1652) -> Alemania | E3: =IF(DATALOG!E1652="","",DATALOG!E1652) -> Australia | F3: =IF(DATALOG!F1652="","",DATALOG!F1652) -> Australia | G3: =IF(DATALOG!G1652="","",DATALOG!G1652) -> Espana | H3: =IF(DATALOG!H1652="","",DATALOG!H1652) -> Espana | I3: =IF(DATALOG!I1652="","",DATALOG!I1652) | J3: =IF(DATALOG!J1652="","",DATALOG!J1652) -> Alemania | ... BL3: =IF(DATALOG!BL1652="","",DATALOG!BL1652)
C4: =IF(DATALOG!C1653="","",DATALOG!C1653) -> Hervidor | D4: =IF(DATALOG!D1653="","",DATALOG!D1653) -> Inventario | E4: =IF(DATALOG!E1653="","",DATALOG!E1653) -> Hervidor | F4: =IF(DATALOG!F1653="","",DATALOG!F1653) -> Inventario | G4: =IF(DATALOG!G1653="","",DATALOG!G1653) -> Hervidor | H4: =IF(DATALOG!H1653="","",DATALOG!H1653) -> Inventario | I4: =IF(DATALOG!I1653="","",DATALOG!I1653) | J4: =IF(DATALOG!J1653="","",DATALOG!J1653) -> Tostador | ... BL4: =IF(DATALOG!BL1653="","",DATALOG!BL1653)
C5: =IF(DATALOG!C1654=0,"",DATALOG!C1654) -> 2 | D5: =IF(DATALOG!D1654=0,"",DATALOG!D1654) -> 2000 | E5: =IF(DATALOG!E1654=0,"",DATALOG!E1654) -> 4 | F5: =IF(DATALOG!F1654=0,"",DATALOG!F1654) -> 5000 | G5: =IF(DATALOG!G1654=0,"",DATALOG!G1654) -> 2 | H5: =IF(DATALOG!H1654=0,"",DATALOG!H1654) -> 5000 | I5: =IF(DATALOG!I1654=0,"",DATALOG!I1654) | J5: =IF(DATALOG!J1654=0,"",DATALOG!J1654) -> 2 | ... BL5: =IF(DATALOG!BL1654=0,"",DATALOG!BL1654)
C6: =IF(DATALOG!C1655=0,"",DATALOG!C1655) -> 7 | D6: =IF(DATALOG!D1655=0,"",DATALOG!D1655) -> 4846 | E6: =IF(DATALOG!E1655=0,"",DATALOG!E1655) -> 6 | F6: =IF(DATALOG!F1655=0,"",DATALOG!F1655) -> 11742 | G6: =IF(DATALOG!G1655=0,"",DATALOG!G1655) -> 4 | H6: =IF(DATALOG!H1655=0,"",DATALOG!H1655) -> 2713 | I6: =IF(DATALOG!I1655=0,"",DATALOG!I1655) | J6: =IF(DATALOG!J1655=0,"",DATALOG!J1655) -> 3 | ... BL6: =IF(DATALOG!BL1655=0,"",DATALOG!BL1655)
C7: =IF(DATALOG!C1656=0,"",DATALOG!C1656) -> 10 | D7: =IF(DATALOG!D1656=0,"",DATALOG!D1656) -> 6500 | E7: =IF(DATALOG!E1656=0,"",DATALOG!E1656) -> 10 | F7: =IF(DATALOG!F1656=0,"",DATALOG!F1656) -> 2412 | G7: =IF(DATALOG!G1656=0,"",DATALOG!G1656) -> 6 | H7: =IF(DATALOG!H1656=0,"",DATALOG!H1656) -> 15000 | I7: =IF(DATALOG!I1656=0,"",DATALOG!I1656) | J7: =IF(DATALOG!J1656=0,"",DATALOG!J1656) -> 7 | ... BL7: =IF(DATALOG!BL1656=0,"",DATALOG!BL1656)
C8: =IF(DATALOG!C1657=0,"",DATALOG!C1657) -> 12 | D8: =IF(DATALOG!D1657=0,"",DATALOG!D1657) -> 10136 | E8: =IF(DATALOG!E1657=0,"",DATALOG!E1657) -> 11 | F8: =IF(DATALOG!F1657=0,"",DATALOG!F1657) -> 7000 | G8: =IF(DATALOG!G1657=0,"",DATALOG!G1657) -> 7 | H8: =IF(DATALOG!H1657=0,"",DATALOG!H1657) -> 14242 | I8: =IF(DATALOG!I1657=0,"",DATALOG!I1657) | J8: =IF(DATALOG!J1657=0,"",DATALOG!J1657) -> 10 | ... BL8: =IF(DATALOG!BL1657=0,"",DATALOG!BL1657)
C9: =IF(DATALOG!C1658=0,"",DATALOG!C1658) -> 13 | D9: =IF(DATALOG!D1658=0,"",DATALOG!D1658) -> 7185 | E9: =IF(DATALOG!E1658=0,"",DATALOG!E1658) -> 12 | F9: =IF(DATALOG!F1658=0,"",DATALOG!F1658) -> 9612 | G9: =IF(DATALOG!G1658=0,"",DATALOG!G1658) -> 8 | H9: =IF(DATALOG!H1658=0,"",DATALOG!H1658) -> 15000 | I9: =IF(DATALOG!I1658=0,"",DATALOG!I1658) | J9: =IF(DATALOG!J1658=0,"",DATALOG!J1658) -> 12 | ... BL9: =IF(DATALOG!BL1658=0,"",DATALOG!BL1658)
C10: =IF(DATALOG!C1659=0,"",DATALOG!C1659) -> 14 | D10: =IF(DATALOG!D1659=0,"",DATALOG!D1659) -> 9250 | E10: =IF(DATALOG!E1659=0,"",DATALOG!E1659) -> 14 | F10: =IF(DATALOG!F1659=0,"",DATALOG!F1659) -> 7105 | G10: =IF(DATALOG!G1659=0,"",DATALOG!G1659) -> 11 | H10: =IF(DATALOG!H1659=0,"",DATALOG!H1659) -> 7100 | I10: =IF(DATALOG!I1659=0,"",DATALOG!I1659) | J10: =IF(DATALOG!J1659=0,"",DATALOG!J1659) -> 13 | ... BL10: =IF(DATALOG!BL1659=0,"",DATALOG!BL1659)
C11: =IF(DATALOG!C1660=0,"",DATALOG!C1660) -> 15 | D11: =IF(DATALOG!D1660=0,"",DATALOG!D1660) -> 19739 | E11: =IF(DATALOG!E1660=0,"",DATALOG!E1660) -> 16 | F11: =IF(DATALOG!F1660=0,"",DATALOG!F1660) -> 9500 | G11: =IF(DATALOG!G1660=0,"",DATALOG!G1660) -> 12 | H11: =IF(DATALOG!H1660=0,"",DATALOG!H1660) -> 7957 | I11: =IF(DATALOG!I1660=0,"",DATALOG!I1660) | J11: =IF(DATALOG!J1660=0,"",DATALOG!J1660) -> 14 | ... BL11: =IF(DATALOG!BL1660=0,"",DATALOG!BL1660)
C12: =IF(DATALOG!C1661=0,"",DATALOG!C1661) -> 16 | D12: =IF(DATALOG!D1661=0,"",DATALOG!D1661) -> 7569 | E12: =IF(DATALOG!E1661=0,"",DATALOG!E1661) -> 17 | F12: =IF(DATALOG!F1661=0,"",DATALOG!F1661) -> 2320 | G12: =IF(DATALOG!G1661=0,"",DATALOG!G1661) -> 13 | H12: =IF(DATALOG!H1661=0,"",DATALOG!H1661) -> 11465 | I12: =IF(DATALOG!I1661=0,"",DATALOG!I1661) | J12: =IF(DATALOG!J1661=0,"",DATALOG!J1661) -> 15 | ... BL12: =IF(DATALOG!BL1661=0,"",DATALOG!BL1661)
C13: =IF(DATALOG!C1662=0,"",DATALOG!C1662) -> 17 | D13: =IF(DATALOG!D1662=0,"",DATALOG!D1662) -> 10000 | E13: =IF(DATALOG!E1662=0,"",DATALOG!E1662) -> 18 | F13: =IF(DATALOG!F1662=0,"",DATALOG!F1662) -> 8000 | G13: =IF(DATALOG!G1662=0,"",DATALOG!G1662) -> 14 | H13: =IF(DATALOG!H1662=0,"",DATALOG!H1662) -> 15000 | I13: =IF(DATALOG!I1662=0,"",DATALOG!I1662) | J13: =IF(DATALOG!J1662=0,"",DATALOG!J1662) -> 16 | ... BL13: =IF(DATALOG!BL1662=0,"",DATALOG!BL1662)
C14: =IF(DATALOG!C1663=0,"",DATALOG!C1663) -> 18 | D14: =IF(DATALOG!D1663=0,"",DATALOG!D1663) -> 6249 | E14: =IF(DATALOG!E1663=0,"",DATALOG!E1663) -> 19 | F14: =IF(DATALOG!F1663=0,"",DATALOG!F1663) -> 31250 | G14: =IF(DATALOG!G1663=0,"",DATALOG!G1663) -> 15 | H14: =IF(DATALOG!H1663=0,"",DATALOG!H1663) -> 8905 | I14: =IF(DATALOG!I1663=0,"",DATALOG!I1663) | J14: =IF(DATALOG!J1663=0,"",DATALOG!J1663) -> 17 | ... BL14: =IF(DATALOG!BL1663=0,"",DATALOG!BL1663)
C15: =IF(DATALOG!C1664=0,"",DATALOG!C1664) -> 19 | D15: =IF(DATALOG!D1664=0,"",DATALOG!D1664) -> 6000 | E15: =IF(DATALOG!E1664=0,"",DATALOG!E1664) -> 20 | F15: =IF(DATALOG!F1664=0,"",DATALOG!F1664) -> 13000 | G15: =IF(DATALOG!G1664=0,"",DATALOG!G1664) -> 16 | H15: =IF(DATALOG!H1664=0,"",DATALOG!H1664) -> 2897 | I15: =IF(DATALOG!I1664=0,"",DATALOG!I1664) | J15: =IF(DATALOG!J1664=0,"",DATALOG!J1664) -> 18 | ... BL15: =IF(DATALOG!BL1664=0,"",DATALOG!BL1664)
C16: =IF(DATALOG!C1665=0,"",DATALOG!C1665) -> 21 | D16: =IF(DATALOG!D1665=0,"",DATALOG!D1665) -> 23654 | E16: =IF(DATALOG!E1665=0,"",DATALOG!E1665) -> 21 | F16: =IF(DATALOG!F1665=0,"",DATALOG!F1665) -> 7000 | G16: =IF(DATALOG!G1665=0,"",DATALOG!G1665) -> 17 | H16: =IF(DATALOG!H1665=0,"",DATALOG!H1665) -> 8056 | I16: =IF(DATALOG!I1665=0,"",DATALOG!I1665) | J16: =IF(DATALOG!J1665=0,"",DATALOG!J1665) -> 19 | ... BL16: =IF(DATALOG!BL1665=0,"",DATALOG!BL1665)
... C1003: =IF(DATALOG!C2652=0,"",DATALOG!C2652) | D1003: =IF(DATALOG!D2652=0,"",DATALOG!D2652) | E1003: =IF(DATALOG!E2652=0,"",DATALOG!E2652) | F1003: =IF(DATALOG!F2652=0,"",DATALOG!F2652) | G1003: =IF(DATALOG!G2652=0,"",DATALOG!G2652) | H1003: =IF(DATALOG!H2652=0,"",DATALOG!H2652) | I1003: =IF(DATALOG!I2652=0,"",DATALOG!I2652) | J1003: =IF(DATALOG!J2652=0,"",DATALOG!J2652) | ... BL1003: =IF(DATALOG!BL2652=0,"",DATALOG!BL2652)

Sheet Manufactura Linea 1
C3: =UPPER(DATALOG!B157) -> INFORME DE PRODUCCION E INVENTARIO
C4: =UPPER(DATALOG!B158) -> COSTO PROMEDIO DE MANUFACTURA PARA CLIMATIZACIO CONSIDERANDO TODA LA INDUSTRIA
C6: =DATALOG!B159 -> Articulo EstufaGas
D7: =DATALOG!C160 -> Alemania | E7: =DATALOG!D160 -> Australia | F7: =DATALOG!E160 -> Espana
C8: =DATALOG!B161 -> Promedio del periodo | D8: =DATALOG!C161 -> 25 | E8: =DATALOG!D161 -> 27.8 | F8: =DATALOG!E161 -> 24.6
C9: =DATALOG!B162 -> Costo minimo para el periodo | D9: =DATALOG!C162 -> 22.8 | E9: =DATALOG!D162 -> 25.4 | F9: =DATALOG!E162 -> 23.2
C10: =DATALOG!B163 -> 0 | D10: =DATALOG!C163 -> 0 | E10: =DATALOG!D163 -> 0 | F10: =DATALOG!E163 -> 0
C11: =DATALOG!B164 -> Total de la produccion (unidades) | D11: =DATALOG!C164 -> 131308 | E11: =DATALOG!D164 -> 127607 | F11: =DATALOG!E164 -> 116749
C12: =DATALOG!B165 -> Turnos producidos | D12: =DATALOG!C165 -> 20 | E12: =DATALOG!D165 -> 19 | F12: =DATALOG!E165 -> 21
C13: =DATALOG!B166 -> Produccion promedio por turno | D13: =DATALOG!C166 -> 6565.4 | E13: =DATALOG!D166 -> 6716.2 | F13: =DATALOG!E166 -> 5559.5
C15: =DATALOG!B168 -> Articulo EstufaElectr
D16: =DATALOG!C169 -> Alemania | E16: =DATALOG!D169 -> Australia | F16: =DATALOG!E169 -> Espana
C17: =DATALOG!B170 -> Promedio del periodo | D17: =DATALOG!C170 -> 31.6 | E17: =DATALOG!D170 -> 36.2 | F17: =DATALOG!E170 -> 33
C18: =DATALOG!B171 -> Costo minimo para el periodo | D18: =DATALOG!C171 -> 28.2 | E18: =DATALOG!D171 -> 32.5 | F18: =DATALOG!E171 -> 30.6
C19: =DATALOG!B172 -> 0 | D19: =DATALOG!C172 -> 0 | E19: =DATALOG!D172 -> 0 | F19: =DATALOG!E172 -> 0
C20: =DATALOG!B173 -> Total de la produccion (unidades) | D20: =DATALOG!C173 -> 128875 | E20: =DATALOG!D173 -> 132590 | F20: =DATALOG!E173 -> 115436
C21: =DATALOG!B174 -> Turnos producidos | D21: =DATALOG!C174 -> 25 | E21: =DATALOG!D174 -> 26 | F21: =DATALOG!E174 -> 26
C22: =DATALOG!B175 -> Produccion promedio por turno | D22: =DATALOG!C175 -> 5155 | E22: =DATALOG!D175 -> 5099.6 | F22: =DATALOG!E175 -> 4439.8
C24: =DATALOG!B177 -> Articulo VentPedestal
D25: =DATALOG!C178 -> Alemania | E25: =DATALOG!D178 -> Australia | F25: =DATALOG!E178 -> Espana
C26: =DATALOG!B179 -> Promedio del periodo | D26: =DATALOG!C179 -> 14.8 | E26: =DATALOG!D179 -> 8.2 | F26: =DATALOG!E179 -> 9.3
C27: =DATALOG!B180 -> Costo minimo para el periodo | D27: =DATALOG!C180 -> 9.1 | E27: =DATALOG!D180 -> 7.8 | F27: =DATALOG!E180 -> 8.7
C28: =DATALOG!B181 -> 0 | D28: =DATALOG!C181 -> 0 | E28: =DATALOG!D181 -> 0 | F28: =DATALOG!E181 -> 0
C29: =DATALOG!B182 -> Total de la produccion (unidades) | D29: =DATALOG!C182 -> 200481 | E29: =DATALOG!D182 -> 99175 | F29: =DATALOG!E182 -> 255734
C30: =DATALOG!B183 -> Turnos producidos | D30: =DATALOG!C183 -> 20 | E30: =DATALOG!D183 -> 10 | F30: =DATALOG!E183 -> 24
C31: =DATALOG!B184 -> Produccion promedio por turno | D31: =DATALOG!C184 -> 10024 | E31: =DATALOG!D184 -> 9917.5 | F31: =DATALOG!E184 -> 10655.6
C33: =DATALOG!B186 -> Articulo Vent_Torre
D34: =DATALOG!C187 -> Alemania | E34: =DATALOG!D187 -> Australia | F34: =DATALOG!E187 -> Espana
C35: =DATALOG!B188 -> Promedio del periodo | D35: =DATALOG!C188 -> 14.9 | E35: =DATALOG!D188 -> 13.9 | F35: =DATALOG!E188 -> 14.6
C36: =DATALOG!B189 -> Costo minimo para el periodo | D36: =DATALOG!C189 -> 14.1 | E36: =DATALOG!D189 -> 12.7 | F36: =DATALOG!E189 -> 13.9
C37: =DATALOG!B190 -> 0 | D37: =DATALOG!C190 -> 0 | E37: =DATALOG!D190 -> 0 | F37: =DATALOG!E190 -> 0
C38: =DATALOG!B191 -> Total de la produccion (unidades) | D38: =DATALOG!C191 -> 253714 | E38: =DATALOG!D191 -> 187502 | F38: =DATALOG!E191 -> 208288
C39: =DATALOG!B192 -> Turnos producidos | D39: =DATALOG!C192 -> 17 | E39: =DATALOG!D192 -> 20 | F39: =DATALOG!E192 -> 26
C40: =DATALOG!B193 -> Produccion promedio por turno | D40: =DATALOG!C193 -> 14924.4 | E40: =DATALOG!D193 -> 9375.1 | F40: =DATALOG!E193 -> 8011.1
C42: =DATALOG!B195 -> Articulo Purif_Aire
D43: =DATALOG!C196 -> Alemania | E43: =DATALOG!D196 -> Australia | F43: =DATALOG!E196 -> Espana
C44: =DATALOG!B197 -> Promedio del periodo | D44: =DATALOG!C197 -> 19.1 | E44: =DATALOG!D197 -> 19.3 | F44: =DATALOG!E197 -> 19.3
C45: =DATALOG!B198 -> Costo minimo para el periodo | D45: =DATALOG!C198 -> 17.2 | E45: =DATALOG!D198 -> 17.1 | F45: =DATALOG!E198 -> 17.9
C46: =DATALOG!B199 -> 0 | D46: =DATALOG!C199 -> 0 | E46: =DATALOG!D199 -> 0 | F46: =DATALOG!E199 -> 0
C47: =DATALOG!B200 -> Total de la produccion (unidades) | D47: =DATALOG!C200 -> 274318 | E47: =DATALOG!D200 -> 148144 | F47: =DATALOG!E200 -> 241266
...

Sheet Manufactura Linea 2
C3: =UPPER(DATALOG!B240) -> INFORME DE PRODUCCION E INVENTARIO
C4: =UPPER(DATALOG!B241) -> COSTO PROMEDIO DE MANUFACTURA PARA ELECTRODOMES CONSIDERANDO TODA LA INDUSTRIA
C6: =DATALOG!B242 -> Articulo Hervidor
D7: =DATALOG!C243 -> Alemania | E7: =DATALOG!D243 -> Australia | F7: =DATALOG!E243 -> Espana
C8: =DATALOG!B244 -> Promedio del periodo | D8: =DATALOG!C244 -> 7.1 | E8: =DATALOG!D244 -> 7.7 | F8: =DATALOG!E244 -> 5.8
C9: =DATALOG!B245 -> Costo minimo para el periodo | D9: =DATALOG!C245 -> 5.4 | E9: =DATALOG!D245 -> 7.3 | F9: =DATALOG!E245 -> 5.4
C10: =DATALOG!B246 -> 0 | D10: =DATALOG!C246 -> 0 | E10: =DATALOG!D246 -> 0 | F10: =DATALOG!E246 -> 0
C11: =DATALOG!B247 -> Total de la produccion (unidades) | D11: =DATALOG!C247 -> 207207 | E11: =DATALOG!D247 -> 209172 | F11: =DATALOG!E247 -> 229019
C12: =DATALOG!B248 -> Turnos producidos | D12: =DATALOG!C248 -> 20 | E12: =DATALOG!D248 -> 18 | F12: =DATALOG!E248 -> 24
C13: =DATALOG!B249 -> Produccion promedio por turno | D13: =DATALOG!C249 -> 10360.4 | E13: =DATALOG!D249 -> 11620.7 | F13: =DATALOG!E249 -> 9542.5
C15: =DATALOG!B251 -> Articulo Tostador
D16: =DATALOG!C252 -> Alemania | E16: =DATALOG!D252 -> Australia | F16: =DATALOG!E252 -> Espana
C17: =DATALOG!B253 -> Promedio del periodo | D17: =DATALOG!C253 -> 4.8 | E17: =DATALOG!D253 -> 5.9 | F17: =DATALOG!E253 -> 5.4
C18: =DATALOG!B254 -> Costo minimo para el periodo | D18: =DATALOG!C254 -> 4.5 | E18: =DATALOG!D254 -> 5.8 | F18: =DATALOG!E254 -> 5.1
C19: =DATALOG!B255 -> 0 | D19: =DATALOG!C255 -> 0 | E19: =DATALOG!D255 -> 0 | F19: =DATALOG!E255 -> 0
C20: =DATALOG!B256 -> Total de la produccion (unidades) | D20: =DATALOG!C256 -> 227421 | E20: =DATALOG!D256 -> 195682 | F20: =DATALOG!E256 -> 249303
C21: =DATALOG!B257 -> Turnos producidos | D21: =DATALOG!C257 -> 14 | E21: =DATALOG!D257 -> 17 | F21: =DATALOG!E257 -> 24
C22: =DATALOG!B258 -> Produccion promedio por turno | D22: =DATALOG!C258 -> 16244.4 | E22: =DATALOG!D258 -> 11510.7 | F22: =DATALOG!E258 -> 10387.6
C24: =DATALOG!B260 -> Articulo Batidora
D25: =DATALOG!C261 -> Alemania | E25: =DATALOG!D261 -> Australia | F25: =DATALOG!E261 -> Espana
C26: =DATALOG!B262 -> Promedio del periodo | D26: =DATALOG!C262 -> 3.5 | E26: =DATALOG!D262 -> 4 | F26: =DATALOG!E262 -> 2.9
C27: =DATALOG!B263 -> Costo minimo para el periodo | D27: =DATALOG!C263 -> 3.1 | E27: =DATALOG!D263 -> 3.7 | F27: =DATALOG!E263 -> 2.6
C28: =DATALOG!B264 -> 0 | D28: =DATALOG!C264 -> 0 | E28: =DATALOG!D264 -> 0 | F28: =DATALOG!E264 -> 0
C29: =DATALOG!B265 -> Total de la produccion (unidades) | D29: =DATALOG!C265 -> 279222 | E29: =DATALOG!D265 -> 135020 | F29: =DATALOG!E265 -> 240113
C30: =DATALOG!B266 -> Turnos producidos | D30: =DATALOG!C266 -> 16 | E30: =DATALOG!D266 -> 16 | F30: =DATALOG!E266 -> 24
C31: =DATALOG!B267 -> Produccion promedio por turno | D31: =DATALOG!C267 -> 17451.4 | E31: =DATALOG!D267 -> 8438.8 | F31: =DATALOG!E267 -> 10004.7
C33: =DATALOG!B269 -> Articulo Cafetera
D34: =DATALOG!C270 -> Alemania | E34: =DATALOG!D270 -> Australia | F34: =DATALOG!E270 -> Espana
C35: =DATALOG!B271 -> Promedio del periodo | D35: =DATALOG!C271 -> 9 | E35: =DATALOG!D271 -> 9.4 | F35: =DATALOG!E271 -> 7
C36: =DATALOG!B272 -> Costo minimo para el periodo | D36: =DATALOG!C272 -> 7.1 | E36: =DATALOG!D272 -> 8.7 | F36: =DATALOG!E272 -> 6.7
C37: =DATALOG!B273 -> 0 | D37: =DATALOG!C273 -> 0 | E37: =DATALOG!D273 -> 0 | F37: =DATALOG!E273 -> 0
C38: =DATALOG!B274 -> Total de la produccion (unidades) | D38: =DATALOG!C274 -> 236963 | E38: =DATALOG!D274 -> 164346 | F38: =DATALOG!E274 -> 245822
C39: =DATALOG!B275 -> Turnos producidos | D39: =DATALOG!C275 -> 24 | E39: =DATALOG!D275 -> 19 | F39: =DATALOG!E275 -> 28
C40: =DATALOG!B276 -> Produccion promedio por turno | D40: =DATALOG!C276 -> 9873.5 | E40: =DATALOG!D276 -> 8649.8 | F40: =DATALOG!E276 -> 8779.4
C42: =DATALOG!B278 -> Articulo Licuadora
D43: =DATALOG!C279 -> Alemania | E43: =DATALOG!D279 -> Australia | F43: =DATALOG!E279 -> Espana
C44: =DATALOG!B280 -> Promedio del periodo | D44: =DATALOG!C280 -> 8 | E44: =DATALOG!D280 -> 9 | F44: =DATALOG!E280 -> 7.2
C45: =DATALOG!B281 -> Costo minimo para el periodo | D45: =DATALOG!C281 -> 7.4 | E45: =DATALOG!D281 -> 8.3 | F45: =DATALOG!E281 -> 6.8
C46: =DATALOG!B282 -> 0 | D46: =DATALOG!C282 -> 0 | E46: =DATALOG!D282 -> 0 | F46: =DATALOG!E282 -> 0
C47: =DATALOG!B283 -> Total de la produccion (unidades) | D47: =DATALOG!C283 -> 164636 | E47: =DATALOG!D283 -> 105891 | F47: =DATALOG!E283 -> 174855
...

Sheet Informacion Linea 1
C1: INFORMACION DETALLADA PARA | D1: =UPPER(DATALOG!C3) -> CLIMATIZACIO
C3: =UPPER(VLOOKUP(1,DATALOG!A1:H320,2,FALSE)) -> INFORMACION DETALLADA DE ALEMANIA PARA CLIMATIZACIO HASTA EL PERIODO 7.
C4: =VLOOKUP(1,DATALOG!A2:H321,2,FALSE) -> Pais | D4: =DATALOG!C2 -> Alemania | E4: =DATALOG!D2 -> Alemania | F4: =DATALOG!E2 -> Alemania | G4: =DATALOG!F2 -> Alemania | H4: =DATALOG!G2 -> Alemania | I4: =DATALOG!H2 -> Alemania | J4: =DATALOG!I2 -> Alemania | K4: =DATALOG!J2 -> 0 | L4: =DATALOG!K2 -> 0
C5: =VLOOKUP(1,DATALOG!A3:H322,2,FALSE) -> Lineas de Productos | D5: =DATALOG!C3 -> Climatizacio | E5: =DATALOG!D3 -> Climatizacio | F5: =DATALOG!E3 -> Climatizacio | G5: =DATALOG!F3 -> Climatizacio | H5: =DATALOG!G3 -> Climatizacio | I5: =DATALOG!H3 -> Climatizacio | J5: =DATALOG!I3 -> Climatizacio | K5: =DATALOG!J3 -> 0 | L5: =DATALOG!K3 -> 0
C6: =VLOOKUP(1,DATALOG!A4:H323,2,FALSE) -> Articulo | D6: =DATALOG!C4 -> EstufaGas | E6: =DATALOG!D4 -> EstufaElectr | F6: =DATALOG!E4 -> VentPedestal | G6: =DATALOG!F4 -> Vent_Torre | H6: =DATALOG!G4 -> Purif_Aire | I6: =DATALOG!H4 -> Deshumidific | J6: =DATALOG!I4 -> Ionizador | K6: =DATALOG!J4 -> 0 | L6: =DATALOG!K4 -> 0
C7: =VLOOKUP(1,DATALOG!A5:H324,2,FALSE) -> Precio promedio historico unidades vendidas a consumidores | D7: =DATALOG!C5 -> 96 | E7: =DATALOG!D5 -> 109.17 | F7: =DATALOG!E5 -> 33.33 | G7: =DATALOG!F5 -> 47.5 | H7: =DATALOG!G5 -> 74.17 | I7: =DATALOG!H5 -> 122 | J7: =DATALOG!I5 -> 80 | K7: =DATALOG!J5 -> 0 | L7: =DATALOG!K5 -> 0
C8: =VLOOKUP(1,DATALOG!A6:H325,2,FALSE) -> Variacion de precio respecto periodo anterior (%) | D8: =DATALOG!C6 -> 0.062 | E8: =DATALOG!D6 -> 0.018 | F8: =DATALOG!E6 -> 0.029 | G8: =DATALOG!F6 -> 0.104 | H8: =DATALOG!G6 -> 0.039 | I8: =DATALOG!H6 -> 0 | J8: =DATALOG!I6 -> 0 | K8: =DATALOG!J6 -> 0 | L8: =DATALOG!K6 -> 0
C9: =VLOOKUP(1,DATALOG!A7:H326,2,FALSE) -> Precio que consumidores estan dispuestos a pagar | D9: =DATALOG!C7 -> 104 | E9: =DATALOG!D7 -> 116 | F9: =DATALOG!E7 -> 34 | G9: =DATALOG!F7 -> 51 | H9: =DATALOG!G7 -> 80 | I9: =DATALOG!H7 -> 120 | J9: =DATALOG!I7 -> 80 | K9: =DATALOG!J7 -> 0 | L9: =DATALOG!K7 -> 0
C10: =VLOOKUP(1,DATALOG!A8:H327,2,FALSE) -> Precio promedio ofrecido a consumidores en periodo 7 | D10: =DATALOG!C8 -> 103 | E10: =DATALOG!D8 -> 111 | F10: =DATALOG!E8 -> 35 | G10: =DATALOG!F8 -> 53 | H10: =DATALOG!G8 -> 79 | I10: =DATALOG!H8 -> 122 | J10: =DATALOG!I8 -> 80 | K10: =DATALOG!J8 -> 0 | L10: =DATALOG!K8 -> 0
C11: =VLOOKUP(1,DATALOG!A9:H328,2,FALSE) -> Ventas a consumidores total | D11: =DATALOG!C9 -> 99459 | E11: =DATALOG!D9 -> 109066 | F11: =DATALOG!E9 -> 69566 | G11: =DATALOG!F9 -> 65213 | H11: =DATALOG!G9 -> 100754 | I11: =DATALOG!H9 -> 46920 | J11: =DATALOG!I9 -> 2000 | K11: =DATALOG!J9 -> 0 | L11: =DATALOG!K9 -> 0
C12: =VLOOKUP(1,DATALOG!A10:H329,2,FALSE) -> Empresas vendiendo a consumidores | D12: =DATALOG!C10 -> 23 | E12: =DATALOG!D10 -> 24 | F12: =DATALOG!E10 -> 23 | G12: =DATALOG!F10 -> 19 | H12: =DATALOG!G10 -> 28 | I12: =DATALOG!H10 -> 13 | J12: =DATALOG!I10 -> 1 | K12: =DATALOG!J10 -> 0 | L12: =DATALOG!K10 -> 0
C13: =VLOOKUP(1,DATALOG!A11:H330,2,FALSE) -> Empresas presentes en mcdo. consumidores con linea de productos | D13: =DATALOG!C11 -> 38 | E13: =DATALOG!D11 -> 38 | F13: =DATALOG!E11 -> 38 | G13: =DATALOG!F11 -> 38 | H13: =DATALOG!G11 -> 38 | I13: =DATALOG!H11 -> 38 | J13: =DATALOG!I11 -> 38 | K13: =DATALOG!J11 -> 0 | L13: =DATALOG!K11 -> 0
C14: =VLOOKUP(1,DATALOG!A12:H331,2,FALSE) -> Inventario final | D14: =DATALOG!C12 -> 289245 | E14: =DATALOG!D12 -> 281434 | F14: =DATALOG!E12 -> 294198 | G14: =DATALOG!F12 -> 370214 | H14: =DATALOG!G12 -> 433254 | I14: =DATALOG!H12 -> 117180 | J14: =DATALOG!I12 -> 79983 | K14: =DATALOG!J12 -> 0 | L14: =DATALOG!K12 -> 0
C15: =VLOOKUP(1,DATALOG!A13:H332,2,FALSE) -> Cantidad producida este periodo | D15: =DATALOG!C13 -> 131308 | E15: =DATALOG!D13 -> 128875 | F15: =DATALOG!E13 -> 200481 | G15: =DATALOG!F13 -> 253714 | H15: =DATALOG!G13 -> 274318 | I15: =DATALOG!H13 -> 19500 | J15: =DATALOG!I13 -> 43959 | K15: =DATALOG!J13 -> 0 | L15: =DATALOG!K13 -> 0
... C19: =VLOOKUP(1,DATALOG!A17:H336,2,FALSE) -> Gasto promedio en Responsabilidad Social | D19: =DATALOG!C17 -> 23154 | E19: =DATALOG!D17 -> 26882 | F19: =DATALOG!E17 -> 21586 | G19: =DATALOG!F17 -> 23215 | H19: =DATALOG!G17 -> 22546 | I19: =DATALOG!H17 -> 27433 | J19: =DATALOG!I17 -> 781 | K19: =DATALOG!J17 -> 0 | L19: =DATALOG!K17 -> 0
C21: =UPPER(DATALOG!B18) -> INFORMACION DETALLADA DE AUSTRALIA PARA CLIMATIZACIO HASTA EL PERIODO 7.
C22: =DATALOG!B19 -> Pais | D22: =DATALOG!C19 -> Australia | E22: =DATALOG!D19 -> Australia | F22: =DATALOG!E19 -> Australia | G22: =DATALOG!F19 -> Australia | H22: =DATALOG!G19 -> Australia | I22: =DATALOG!H19 -> Australia | J22: =DATALOG!I19 -> Australia | ... L22: =DATALOG!K19 -> 0
C23: =DATALOG!B20 -> Lineas de Productos | D23: =DATALOG!C20 -> Climatizacio | E23: =DATALOG!D20 -> Climatizacio | F23: =DATALOG!E20 -> Climatizacio | G23: =DATALOG!F20 -> Climatizacio | H23: =DATALOG!G20 -> Climatizacio | I23: =DATALOG!H20 -> Climatizacio | J23: =DATALOG!I20 -> Climatizacio | ... L23: =DATALOG!K20 -> 0
C24: =DATALOG!B21 -> Articulo | D24: =DATALOG!C21 -> EstufaGas | E24: =DATALOG!D21 -> EstufaElectr | F24: =DATALOG!E21 -> VentPedestal | G24: =DATALOG!F21 -> Vent_Torre | H24: =DATALOG!G21 -> Purif_Aire | I24: =DATALOG!H21 -> Deshumidific | J24: =DATALOG!I21 -> Ionizador | ... L24: =DATALOG!K21 -> 0
C25: =DATALOG!B22 -> Precio promedio historico unidades vendidas a consumidores | D25: =DATALOG!C22 -> 96.5 | E25: =DATALOG!D22 -> 128.17 | F25: =DATALOG!E22 -> 41.33 | G25: =DATALOG!F22 -> 58.33 | H25: =DATALOG!G22 -> 81.83 | I25: =DATALOG!H22 -> 122 | J25: =DATALOG!I22 -> 80 | ... L25: =DATALOG!K22 -> 0
C26: =DATALOG!B23 -> Variacion de precio respecto periodo anterior (%) | D26: =DATALOG!C23 -> 0.04 | E26: =DATALOG!D23 -> -0.023 | F26: =DATALOG!E23 -> 0.048 | G26: =DATALOG!F23 -> 0.051 | H26: =DATALOG!G23 -> 0.012 | I26: =DATALOG!H23 -> 0 | J26: =DATALOG!I23 -> 0 | ... L26: =DATALOG!K23 -> 0
C27: =DATALOG!B24 -> Precio que consumidores estan dispuestos a pagar | D27: =DATALOG!C24 -> 103 | E27: =DATALOG!D24 -> 134 | F27: =DATALOG!E24 -> 44 | G27: =DATALOG!F24 -> 62 | H27: =DATALOG!G24 -> 88 | I27: =DATALOG!H24 -> 115 | J27: =DATALOG!I24 -> 80 | ... L27: =DATALOG!K24 -> 0
C28: =DATALOG!B25 -> Precio promedio ofrecido a consumidores en periodo 7 | D28: =DATALOG!C25 -> 104 | E28: =DATALOG!D25 -> 129 | F28: =DATALOG!E25 -> 44 | G28: =DATALOG!F25 -> 62 | H28: =DATALOG!G25 -> 86 | I28: =DATALOG!H25 -> 122 | J28: =DATALOG!I25 -> 80 | ... L28: =DATALOG!K25 -> 0
C29: =DATALOG!B26 -> Ventas a consumidores total | D29: =DATALOG!C26 -> 44719 | E29: =DATALOG!D26 -> 34434 | F29: =DATALOG!E26 -> 165788 | G29: =DATALOG!F26 -> 143347 | H29: =DATALOG!G26 -> 152006 | I29: =DATALOG!H26 -> 38328 | J29: =DATALOG!I26 -> 2784 | ... L29: =DATALOG!K26 -> 0
C30: =DATALOG!B27 -> Empresas vendiendo a consumidores | D30: =DATALOG!C27 -> 14 | E30: =DATALOG!D27 -> 12 | F30: =DATALOG!E27 -> 30 | G30: =DATALOG!F27 -> 25 | H30: =DATALOG!G27 -> 27 | I30: =DATALOG!H27 -> 7 | J30: =DATALOG!I27 -> 1 | ... L30: =DATALOG!K27 -> 0
C31: =DATALOG!B28 -> Empresas presentes en mcdo. consumidores con linea de productos | D31: =DATALOG!C28 -> 35 | E31: =DATALOG!D28 -> 35 | F31: =DATALOG!E28 -> 35 | G31: =DATALOG!F28 -> 35 | H31: =DATALOG!G28 -> 35 | I31: =DATALOG!H28 -> 35 | J31: =DATALOG!I28 -> 35 | ... L31: =DATALOG!K28 -> 0
C32: =DATALOG!B29 -> Inventario final | D32: =DATALOG!C29 -> 177790 | E32: =DATALOG!D29 -> 196372 | F32: =DATALOG!E29 -> 396410 | G32: =DATALOG!F29 -> 491533 | H32: =DATALOG!G29 -> 382583 | I32: =DATALOG!H29 -> 133033 | J32: =DATALOG!I29 -> 107490 | ... L32: =DATALOG!K29 -> 0
C33: =DATALOG!B30 -> Cantidad producida este periodo | D33: =DATALOG!C30 -> 127607 | E33: =DATALOG!D30 -> 132590 | F33: =DATALOG!E30 -> 99175 | G33: =DATALOG!F30 -> 187502 | H33: =DATALOG!G30 -> 148144 | I33: =DATALOG!H30 -> 37947 | J33: =DATALOG!I30 -> 51525 | ... L33: =DATALOG!K30 -> 0
